Workbook

Sheet 工数管理
A1: assetID | B1: task | C1: assign | D1: 工数 | E1: 使用 | F1: 残 | G1: 消化率 | H1: status | I1: day | J1: FIX | K1: 1 | M1: 2 | O1: 3 | Q1: 4 | S1: 5 | U1: 6 | W1: 7 | Y1: 8 | AA1: 9 | AC1: 10 | AE1: 11 | AG1: 12 | AI1: =TODAY() -> 46302
K2: 開始 | L2: 中断 | M2: 開始 | N2: 中断 | O2: 開始 | P2: 中断 | Q2: 開始 | R2: 中断 | S2: 開始 | T2: 中断 | U2: 開始 | V2: 中断 | W2: 開始 | X2: 中断 | Y2: 開始 | Z2: 中断 | AA2: 開始 | AB2: 中断 | AC2: 開始 | AD2: 中断 | AE2: 開始 | AF2: 中断 | AG2: 開始 | AH2: 中断
A3: CH01 | B3: =IF($A3="","",COUNTIFS($AK$3:$AK$98,$A3,$AL$3:$AL$98,"作業中")) -> 1 | D3: =IF($A3="","",SUMIFS($AM$3:$AM$98,$AK$3:$AK$98,$A3)) -> 120 | E3: =IF($A3="","",SUMIFS($AN$3:$AN$98,$AK$3:$AK$98,$A3)) -> 68 | F3: =IF($A3="","",SUMIFS($AO$3:$AO$98,$AK$3:$AK$98,$A3,$AL$3:$AL$98,"<>FIX")) -> 52 | G3: =IF($A3="","",IFERROR(AVERAGEIFS($BO$3:$BO$98,$AK$3:$AK$98,$A3,$AL$3:$AL$98,"FIX"),"")) -> 1 | H3: =IF($A3="","",IF(COUNTIFS($AK$3:$AK$98,$A3,$AL$3:$AL$98,"作業中")>0,IF(SUMIFS($AO$3:$AO$98,$AK$3:$AK$98,$A3,$AL$3:$AL$98,"作業中")<=0,"工数超過","作業中"),IF(COUNTIFS($AK$3:$AK$98,$A3,$AL$3:$AL$98,"中断")>0,"作業待ち",IF(COUNTIFS($AK$3:$AK$98,$A3,$AL$3:$AL$98,"未着手")>0,"着手待ち","空き")))) -> 作業中 | I3: =IF($A3="","",祝日!J4) -> 17 | AJ3: =IF($A3="","-",$A3) -> CH01 | BP3: =ROW() -> 3
B4: =IF($A4="","","total") | D4: =IF($A4="","",SUM(D5:D7)) | E4: =IF($A4="","",SUM(E5:E7)) | F4: =IF($A4="","",D4-E4) | G4: =IF($A4="","",IFERROR(AVERAGEIFS(G5:G7,H5:H7,"<>未着手",H5:H7,"<>作業中"),""))
A5: =IF($A4="","",$A4) | B5: =IF($A4="","","low") | E5: =IF(AND($D5="",COUNT($K5:$AH5)=0),"",IF(K5="",0,MAX(0,NETWORKDAYS(K5,IF(L5<>"",L5,IF($J5<>"",K5,$AI$1)),祝日!$A$2:$A$200)))+IF(M5="",0,MAX(0,NETWORKDAYS(M5,IF(N5<>"",N5,IF($J5<>"",M5,$AI$1)),祝日!$A$2:$A$200)))+IF(O5="",0,MAX(0,NETWORKDAYS(O5,IF(P5<>"",P5,IF($J5<>"",O5,$AI$1)),祝日!$A$2:$A$200)))+IF(Q5="",0,MAX(0,NETWORKDAYS(Q5,IF(R5<>"",R5,IF($J5<>"",Q5,$AI$1)),祝日!$A$2:$A$200)))+IF(S5="",0,MAX(0,NETWORKDAYS(S5,IF(T5<>"",T5,IF($J5<>"",S5,$AI$1)),祝日!$A$2:$A$200)))+IF(U5="",0,MAX(0,NETWORKDAYS(U5,IF(V5<>"",V5,IF($J5<>"",U5,$AI$1)),祝日!$A$2:$A$200)))+IF(W5="",0,MAX(0,NETWORKDAYS(W5,IF(X5<>"",X5,IF($J5<>"",W5,$AI$1)),祝日!$A$2:$A$200)))+IF(Y5="",0,MAX(0,NETWORKDAYS(Y5,IF(Z5<>"",Z5,IF($J5<>"",Y5,$AI$1)),祝日!$A$2:$A$200)))+IF(AA5="",0,MAX(0,NETWORKDAYS(AA5,IF(AB5<>"",AB5,IF($J5<>"",AA5,$AI$1)),祝日!$A$2:$A$200)))+IF(AC5="",0,MAX(0,NETWORKDAYS(AC5,IF(AD5<>"",AD5,IF($J5<>"",AC5,$AI$1)),祝日!$A$2:$A$200)))+IF(AE5="",0,MAX(0,NETWORKDAYS(AE5,IF(AF5<>"",AF5,IF($J5<>"",AE5,$AI$1)),祝日!$A$2:$A$200)))+IF(AG5="",0,MAX(0,NETWORKDAYS(AG5,IF(AH5<>"",AH5,IF($J5<>"",AG5,$AI$1)),祝日!$A$2:$A$200)))) | F5: =IF($D5="","",$D5-$E5) | G5: =IF(OR($D5="",$D5=0),"",$E5/$D5) | H5: =IF($D5="","",IF($J5<>"","FIX",IF(AND(SUMPRODUCT((MOD(COLUMN($K5:$AH5)-COLUMN($K5),2)=0)*($K5:$AH5<>""))=0,SUMPRODUCT((MOD(COLUMN($K5:$AH5)-COLUMN($K5),2)=1)*($K5:$AH5<>""))=0),"未着手",IF(SUMPRODUCT((MOD(COLUMN($K5:$AH5)-COLUMN($K5),2)=0)*($K5:$AH5<>""))>SUMPRODUCT((MOD(COLUMN($K5:$AH5)-COLUMN($K5),2)=1)*($K5:$AH5<>"")),"作業中","中断")))) | I5: =IF($H5="中断",MAX(0,$AI$1-MAX(L5,N5,P5,R5,T5,V5,X5,Z5,AB5,AD5,AF5,AH5)),"") | AK5: =IF($A4="","",IF(LOOKUP(2,1/($AJ$3:$AJ5<>""),$AJ$3:$AJ5)="-","",LOOKUP(2,1/($AJ$3:$AJ5<>""),$AJ$3:$AJ5))) | AL5: =$H5 | AM5: =IF(ISNUMBER($D5),$D5,0) -> 0 | AN5: =IF(ISNUMBER($E5),$E5,0) -> 0 | AO5: =IF(ISNUMBER($F5),$F5,0) -> 0 | AQ5: =IF(OR($AK5="",K5="",L5=""),0,COUNTIFS($AK$3:$AK$98,$AK5,K$3:K$98,"<"&L5,L$3:L$98,">"&K5)+COUNTIFS($AK$3:$AK$98,$AK5,M$3:M$98,"<"&L5,N$3:N$98,">"&K5)+COUNTIFS($AK$3:$AK$98,$AK5,O$3:O$98,"<"&L5,P$3:P$98,">"&K5)+COUNTIFS($AK$3:$AK$98,$AK5,Q$3:Q$98,"<"&L5,R$3:R$98,">"&K5)+COUNTIFS($AK$3:$AK$98,$AK5,S$3:S$98,"<"&L5,T$3:T$98,">"&K5)+COUNTIFS($AK$3:$AK$98,$AK5,U$3:U$98,"<"&L5,V$3:V$98,">"&K5)+COUNTIFS($AK$3:$AK$98,$AK5,W$3:W$98,"<"&L5,X$3:X$98,">"&K5)+COUNTIFS($AK$3:$AK$98,$AK5,Y$3:Y$98,"<"&L5,Z$3:Z$98,">"&K5)+COUNTIFS($AK$3:$AK$98,$AK5,AA$3:AA$98,"<"&L5,AB$3:AB$98,">"&K5)+COUNTIFS($AK$3:$AK$98,$AK5,AC$3:AC$98,"<"&L5,AD$3:AD$98,">"&K5)+COUNTIFS($AK$3:$AK$98,$AK5,AE$3:AE$98,"<"&L5,AF$3:AF$98,">"&K5)+COUNTIFS($AK$3:$AK$98,$AK5,AG$3:AG$98,"<"&L5,AH$3:AH$98,">"&K5)-(K5<L5)) -> 0 | AR5: =AQ5 -> 0 | AS5: =IF(OR($AK5="",M5="",N5=""),0,COUNTIFS($AK$3:$AK$98,$AK5,K$3:K$98,"<"&N5,L$3:L$98,">"&M5)+COUNTIFS($AK$3:$AK$98,$AK5,M$3:M$98,"<"&N5,N$3:N$98,">"&M5)+COUNTIFS($AK$3:$AK$98,$AK5,O$3:O$98,"<"&N5,P$3:P$98,">"&M5)+COUNTIFS($AK$3:$AK$98,$AK5,Q$3:Q$98,"<"&N5,R$3:R$98,">"&M5)+COUNTIFS($AK$3:$AK$98,$AK5,S$3:S$98,"<"&N5,T$3:T$98,">"&M5)+COUNTIFS($AK$3:$AK$98,$AK5,U$3:U$98,"<"&N5,V$3:V$98,">"&M5)+COUNTIFS($AK$3:$AK$98,$AK5,W$3:W$98,"<"&N5,X$3:X$98,">"&M5)+COUNTIFS($AK$3:$AK$98,$AK5,Y$3:Y$98,"<"&N5,Z$3:Z$98,">"&M5)+COUNTIFS($AK$3:$AK$98,$AK5,AA$3:AA$98,"<"&N5,AB$3:AB$98,">"&M5)+COUNTIFS($AK$3:$AK$98,$AK5,AC$3:AC$98,"<"&N5,AD$3:AD$98,">"&M5)+COUNTIFS($AK$3:$AK$98,$AK5,AE$3:AE$98,"<"&N5,AF$3:AF$98,">"&M5)+COUNTIFS($AK$3:$AK$98,$AK5,AG$3:AG$98,"<"&N5,AH$3:AH$98,">"&M5)-(M5<N5)) -> 0 | AT5: =AS5 -> 0 | AU5: =IF(OR($AK5="",O5="",P5=""),0,COUNTIFS($AK$3:$AK$98,$AK5,K$3:K$98,"<"&P5,L$3:L$98,">"&O5)+COUNTIFS($AK$3:$AK$98,$AK5,M$3:M$98,"<"&P5,N$3:N$98,">"&O5)+COUNTIFS($AK$3:$AK$98,$AK5,O$3:O$98,"<"&P5,P$3:P$98,">"&O5)+COUNTIFS($AK$3:$AK$98,$AK5,Q$3:Q$98,"<"&P5,R$3:R$98,">"&O5)+COUNTIFS($AK$3:$AK$98,$AK5,S$3:S$98,"<"&P5,T$3:T$98,">"&O5)+COUNTIFS($AK$3:$AK$98,$AK5,U$3:U$98,"<"&P5,V$3:V$98,">"&O5)+COUNTIFS($AK$3:$AK$98,$AK5,W$3:W$98,"<"&P5,X$3:X$98,">"&O5)+COUNTIFS($AK$3:$AK$98,$AK5,Y$3:Y$98,"<"&P5,Z$3:Z$98,">"&O5)+COUNTIFS($AK$3:$AK$98,$AK5,AA$3:AA$98,"<"&P5,AB$3:AB$98,">"&O5)+COUNTIFS($AK$3:$AK$98,$AK5,AC$3:AC$98,"<"&P5,AD$3:AD$98,">"&O5)+COUNTIFS($AK$3:$AK$98,$AK5,AE$3:AE$98,"<"&P5,AF$3:AF$98,">"&O5)+COUNTIFS($AK$3:$AK$98,$AK5,AG$3:AG$98,"<"&P5,AH$3:AH$98,">"&O5)-(O5<P5)) -> 0 | AV5: =AU5 -> 0 | AW5: =IF(OR($AK5="",Q5="",R5=""),0,COUNTIFS($AK$3:$AK$98,$AK5,K$3:K$98,"<"&R5,L$3:L$98,">"&Q5)+COUNTIFS($AK$3:$AK$98,$AK5,M$3:M$98,"<"&R5,N$3:N$98,">"&Q5)+COUNTIFS($AK$3:$AK$98,$AK5,O$3:O$98,"<"&R5,P$3:P$98,">"&Q5)+COUNTIFS($AK$3:$AK$98,$AK5,Q$3:Q$98,"<"&R5,R$3:R$98,">"&Q5)+COUNTIFS($AK$3:$AK$98,$AK5,S$3:S$98,"<"&R5,T$3:T$98,">"&Q5)+COUNTIFS($AK$3:$AK$98,$AK5,U$3:U$98,"<"&R5,V$3:V$98,">"&Q5)+COUNTIFS($AK$3:$AK$98,$AK5,W$3:W$98,"<"&R5,X$3:X$98,">"&Q5)+COUNTIFS($AK$3:$AK$98,$AK5,Y$3:Y$98,"<"&R5,Z$3:Z$98,">"&Q5)+COUNTIFS($AK$3:$AK$98,$AK5,AA$3:AA$98,"<"&R5,AB$3:AB$98,">"&Q5)+COUNTIFS($AK$3:$AK$98,$AK5,AC$3:AC$98,"<"&R5,AD$3:AD$98,">"&Q5)+COUNTIFS($AK$3:$AK$98,$AK5,AE$3:AE$98,"<"&R5,AF$3:AF$98,">"&Q5)+COUNTIFS($AK$3:$AK$98,$AK5,AG$3:AG$98,"<"&R5,AH$3:AH$98,">"&Q5)-(Q5<R5)) -> 0 | AX5: =AW5 -> 0 | AY5: =IF(OR($AK5="",S5="",T5=""),0,COUNTIFS($AK$3:$AK$98,$AK5,K$3:K$98,"<"&T5,L$3:L$98,">"&S5)+COUNTIFS($AK$3:$AK$98,$AK5,M$3:M$98,"<"&T5,N$3:N$98,">"&S5)+COUNTIFS($AK$3:$AK$98,$AK5,O$3:O$98,"<"&T5,P$3:P$98,">"&S5)+COUNTIFS($AK$3:$AK$98,$AK5,Q$3:Q$98,"<"&T5,R$3:R$98,">"&S5)+COUNTIFS($AK$3:$AK$98,$AK5,S$3:S$98,"<"&T5,T$3:T$98,">"&S5)+COUNTIFS($AK$3:$AK$98,$AK5,U$3:U$98,"<"&T5,V$3:V$98,">"&S5)+COUNTIFS($AK$3:$AK$98,$AK5,W$3:W$98,"<"&T5,X$3:X$98,">"&S5)+COUNTIFS($AK$3:$AK$98,$AK5,Y$3:Y$98,"<"&T5,Z$3:Z$98,">"&S5)+COUNTIFS($AK$3:$AK$98,$AK5,AA$3:AA$98,"<"&T5,AB$3:AB$98,">"&S5)+COUNTIFS($AK$3:$AK$98,$AK5,AC$3:AC$98,"<"&T5,AD$3:AD$98,">"&S5)+COUNTIFS($AK$3:$AK$98,$AK5,AE$3:AE$98,"<"&T5,AF$3:AF$98,">"&S5)+COUNTIFS($AK$3:$AK$98,$AK5,AG$3:AG$98,"<"&T5,AH$3:AH$98,">"&S5)-(S5<T5)) -> 0 | AZ5: =AY5 -> 0 | BA5: =IF(OR($AK5="",U5="",V5=""),0,COUNTIFS($AK$3:$AK$98,$AK5,K$3:K$98,"<"&V5,L$3:L$98,">"&U5)+COUNTIFS($AK$3:$AK$98,$AK5,M$3:M$98,"<"&V5,N$3:N$98,">"&U5)+COUNTIFS($AK$3:$AK$98,$AK5,O$3:O$98,"<"&V5,P$3:P$98,">"&U5)+COUNTIFS($AK$3:$AK$98,$AK5,Q$3:Q$98,"<"&V5,R$3:R$98,">"&U5)+COUNTIFS($AK$3:$AK$98,$AK5,S$3:S$98,"<"&V5,T$3:T$98,">"&U5)+COUNTIFS($AK$3:$AK$98,$AK5,U$3:U$98,"<"&V5,V$3:V$98,">"&U5)+COUNTIFS($AK$3:$AK$98,$AK5,W$3:W$98,"<"&V5,X$3:X$98,">"&U5)+COUNTIFS($AK$3:$AK$98,$AK5,Y$3:Y$98,"<"&V5,Z$3:Z$98,">"&U5)+COUNTIFS($AK$3:$AK$98,$AK5,AA$3:AA$98,"<"&V5,AB$3:AB$98,">"&U5)+COUNTIFS($AK$3:$AK$98,$AK5,AC$3:AC$98,"<"&V5,AD$3:AD$98,">"&U5)+COUNTIFS($AK$3:$AK$98,$AK5,AE$3:AE$98,"<"&V5,AF$3:AF$98,">"&U5)+COUNTIFS($AK$3:$AK$98,$AK5,AG$3:AG$98,"<"&V5,AH$3:AH$98,">"&U5)-(U5<V5)) -> 0 | BB5: =BA5 -> 0 | BC5: =IF(OR($AK5="",W5="",X5=""),0,COUNTIFS($AK$3:$AK$98,$AK5,K$3:K$98,"<"&X5,L$3:L$98,">"&W5)+COUNTIFS($AK$3:$AK$98,$AK5,M$3:M$98,"<"&X5,N$3:N$98,">"&W5)+COUNTIFS($AK$3:$AK$98,$AK5,O$3:O$98,"<"&X5,P$3:P$98,">"&W5)+COUNTIFS($AK$3:$AK$98,$AK5,Q$3:Q$98,"<"&X5,R$3:R$98,">"&W5)+COUNTIFS($AK$3:$AK$98,$AK5,S$3:S$98,"<"&X5,T$3:T$98,">"&W5)+COUNTIFS($AK$3:$AK$98,$AK5,U$3:U$98,"<"&X5,V$3:V$98,">"&W5)+COUNTIFS($AK$3:$AK$98,$AK5,W$3:W$98,"<"&X5,X$3:X$98,">"&W5)+COUNTIFS($AK$3:$AK$98,$AK5,Y$3:Y$98,"<"&X5,Z$3:Z$98,">"&W5)+COUNTIFS($AK$3:$AK$98,$AK5,AA$3:AA$98,"<"&X5,AB$3:AB$98,">"&W5)+COUNTIFS($AK$3:$AK$98,$AK5,AC$3:AC$98,"<"&X5,AD$3:AD$98,">"&W5)+COUNTIFS($AK$3:$AK$98,$AK5,AE$3:AE$98,"<"&X5,AF$3:AF$98,">"&W5)+COUNTIFS($AK$3:$AK$98,$AK5,AG$3:AG$98,"<"&X5,AH$3:AH$98,">"&W5)-(W5<X5)) -> 0 | BD5: =BC5 -> 0 | BE5: =IF(OR($AK5="",Y5="",Z5=""),0,COUNTIFS($AK$3:$AK$98,$AK5,K$3:K$98,"<"&Z5,L$3:L$98,">"&Y5)+COUNTIFS($AK$3:$AK$98,$AK5,M$3:M$98,"<"&Z5,N$3:N$98,">"&Y5)+COUNTIFS($AK$3:$AK$98,$AK5,O$3:O$98,"<"&Z5,P$3:P$98,">"&Y5)+COUNTIFS($AK$3:$AK$98,$AK5,Q$3:Q$98,"<"&Z5,R$3:R$98,">"&Y5)+COUNTIFS($AK$3:$AK$98,$AK5,S$3:S$98,"<"&Z5,T$3:T$98,">"&Y5)+COUNTIFS($AK$3:$AK$98,$AK5,U$3:U$98,"<"&Z5,V$3:V$98,">"&Y5)+COUNTIFS($AK$3:$AK$98,$AK5,W$3:W$98,"<"&Z5,X$3:X$98,">"&Y5)+COUNTIFS($AK$3:$AK$98,$AK5,Y$3:Y$98,"<"&Z5,Z$3:Z$98,">"&Y5)+COUNTIFS($AK$3:$AK$98,$AK5,AA$3:AA$98,"<"&Z5,AB$3:AB$98,">"&Y5)+COUNTIFS($AK$3:$AK$98,$AK5,AC$3:AC$98,"<"&Z5,AD$3:AD$98,">"&Y5)+COUNTIFS($AK$3:$AK$98,$AK5,AE$3:AE$98,"<"&Z5,AF$3:AF$98,">"&Y5)+COUNTIFS($AK$3:$AK$98,$AK5,AG$3:AG$98,"<"&Z5,AH$3:AH$98,">"&Y5)-(Y5<Z5)) -> 0 | BF5: =BE5 -> 0 | BG5: =IF(OR($AK5="",AA5="",AB5=""),0,COUNTIFS($AK$3:$AK$98,$AK5,K$3:K$98,"<"&AB5,L$3:L$98,">"&AA5)+COUNTIFS($AK$3:$AK$98,$AK5,M$3:M$98,"<"&AB5,N$3:N$98,">"&AA5)+COUNTIFS($AK$3:$AK$98,$AK5,O$3:O$98,"<"&AB5,P$3:P$98,">"&AA5)+COUNTIFS($AK$3:$AK$98,$AK5,Q$3:Q$98,"<"&AB5,R$3:R$98,">"&AA5)+COUNTIFS($AK$3:$AK$98,$AK5,S$3:S$98,"<"&AB5,T$3:T$98,">"&AA5)+COUNTIFS($AK$3:$AK$98,$AK5,U$3:U$98,"<"&AB5,V$3:V$98,">"&AA5)+COUNTIFS($AK$3:$AK$98,$AK5,W$3:W$98,"<"&AB5,X$3:X$98,">"&AA5)+COUNTIFS($AK$3:$AK$98,$AK5,Y$3:Y$98,"<"&AB5,Z$3:Z$98,">"&AA5)+COUNTIFS($AK$3:$AK$98,$AK5,AA$3:AA$98,"<"&AB5,AB$3:AB$98,">"&AA5)+COUNTIFS($AK$3:$AK$98,$AK5,AC$3:AC$98,"<"&AB5,AD$3:AD$98,">"&AA5)+COUNTIFS($AK$3:$AK$98,$AK5,AE$3:AE$98,"<"&AB5,AF$3:AF$98,">"&AA5)+COUNTIFS($AK$3:$AK$98,$AK5,AG$3:AG$98,"<"&AB5,AH$3:AH$98,">"&AA5)-(AA5<AB5)) -> 0 | BH5: =BG5 -> 0 | BI5: =IF(OR($AK5="",AC5="",AD5=""),0,COUNTIFS($AK$3:$AK$98,$AK5,K$3:K$98,"<"&AD5,L$3:L$98,">"&AC5)+COUNTIFS($AK$3:$AK$98,$AK5,M$3:M$98,"<"&AD5,N$3:N$98,">"&AC5)+COUNTIFS($AK$3:$AK$98,$AK5,O$3:O$98,"<"&AD5,P$3:P$98,">"&AC5)+COUNTIFS($AK$3:$AK$98,$AK5,Q$3:Q$98,"<"&AD5,R$3:R$98,">"&AC5)+COUNTIFS($AK$3:$AK$98,$AK5,S$3:S$98,"<"&AD5,T$3:T$98,">"&AC5)+COUNTIFS($AK$3:$AK$98,$AK5,U$3:U$98,"<"&AD5,V$3:V$98,">"&AC5)+COUNTIFS($AK$3:$AK$98,$AK5,W$3:W$98,"<"&AD5,X$3:X$98,">"&AC5)+COUNTIFS($AK$3:$AK$98,$AK5,Y$3:Y$98,"<"&AD5,Z$3:Z$98,">"&AC5)+COUNTIFS($AK$3:$AK$98,$AK5,AA$3:AA$98,"<"&AD5,AB$3:AB$98,">"&AC5)+COUNTIFS($AK$3:$AK$98,$AK5,AC$3:AC$98,"<"&AD5,AD$3:AD$98,">"&AC5)+COUNTIFS($AK$3:$AK$98,$AK5,AE$3:AE$98,"<"&AD5,AF$3:AF$98,">"&AC5)+COUNTIFS($AK$3:$AK$98,$AK5,AG$3:AG$98,"<"&AD5,AH$3:AH$98,">"&AC5)-(AC5<AD5)) -> 0 | BJ5: =BI5 -> 0 | BK5: =IF(OR($AK5="",AE5="",AF5=""),0,COUNTIFS($AK$3:$AK$98,$AK5,K$3:K$98,"<"&AF5,L$3:L$98,">"&AE5)+COUNTIFS($AK$3:$AK$98,$AK5,M$3:M$98,"<"&AF5,N$3:N$98,">"&AE5)+COUNTIFS($AK$3:$AK$98,$AK5,O$3:O$98,"<"&AF5,P$3:P$98,">"&AE5)+COUNTIFS($AK$3:$AK$98,$AK5,Q$3:Q$98,"<"&AF5,R$3:R$98,">"&AE5)+COUNTIFS($AK$3:$AK$98,$AK5,S$3:S$98,"<"&AF5,T$3:T$98,">"&AE5)+COUNTIFS($AK$3:$AK$98,$AK5,U$3:U$98,"<"&AF5,V$3:V$98,">"&AE5)+COUNTIFS($AK$3:$AK$98,$AK5,W$3:W$98,"<"&AF5,X$3:X$98,">"&AE5)+COUNTIFS($AK$3:$AK$98,$AK5,Y$3:Y$98,"<"&AF5,Z$3:Z$98,">"&AE5)+COUNTIFS($AK$3:$AK$98,$AK5,AA$3:AA$98,"<"&AF5,AB$3:AB$98,">"&AE5)+COUNTIFS($AK$3:$AK$98,$AK5,AC$3:AC$98,"<"&AF5,AD$3:AD$98,">"&AE5)+COUNTIFS($AK$3:$AK$98,$AK5,AE$3:AE$98,"<"&AF5,AF$3:AF$98,">"&AE5)+COUNTIFS($AK$3:$AK$98,$AK5,AG$3:AG$98,"<"&AF5,AH$3:AH$98,">"&AE5)-(AE5<AF5)) -> 0 | BL5: =BK5 -> 0 | BM5: =IF(OR($AK5="",AG5="",AH5=""),0,COUNTIFS($AK$3:$AK$98,$AK5,K$3:K$98,"<"&AH5,L$3:L$98,">"&AG5)+COUNTIFS($AK$3:$AK$98,$AK5,M$3:M$98,"<"&AH5,N$3:N$98,">"&AG5)+COUNTIFS($AK$3:$AK$98,$AK5,O$3:O$98,"<"&AH5,P$3:P$98,">"&AG5)+COUNTIFS($AK$3:$AK$98,$AK5,Q$3:Q$98,"<"&AH5,R$3:R$98,">"&AG5)+COUNTIFS($AK$3:$AK$98,$AK5,S$3:S$98,"<"&AH5,T$3:T$98,">"&AG5)+COUNTIFS($AK$3:$AK$98,$AK5,U$3:U$98,"<"&AH5,V$3:V$98,">"&AG5)+COUNTIFS($AK$3:$AK$98,$AK5,W$3:W$98,"<"&AH5,X$3:X$98,">"&AG5)+COUNTIFS($AK$3:$AK$98,$AK5,Y$3:Y$98,"<"&AH5,Z$3:Z$98,">"&AG5)+COUNTIFS($AK$3:$AK$98,$AK5,AA$3:AA$98,"<"&AH5,AB$3:AB$98,">"&AG5)+COUNTIFS($AK$3:$AK$98,$AK5,AC$3:AC$98,"<"&AH5,AD$3:AD$98,">"&AG5)+COUNTIFS($AK$3:$AK$98,$AK5,AE$3:AE$98,"<"&AH5,AF$3:AF$98,">"&AG5)+COUNTIFS($AK$3:$AK$98,$AK5,AG$3:AG$98,"<"&AH5,AH$3:AH$98,">"&AG5)-(AG5<AH5)) -> 0 | BN5: =BM5 -> 0 | BO5: =IF(ISNUMBER($G5),$G5,"") | BP5: =IF(AND($A5<>"",COUNT($K5:$AH5)>0),ROW(),"")
A6: =IF($A4="","",$A4) | B6: =IF($A4="","","high") | E6: =IF(AND($D6="",COUNT($K6:$AH6)=0),"",IF(K6="",0,MAX(0,NETWORKDAYS(K6,IF(L6<>"",L6,IF($J6<>"",K6,$AI$1)),祝日!$A$2:$A$200)))+IF(M6="",0,MAX(0,NETWORKDAYS(M6,IF(N6<>"",N6,IF($J6<>"",M6,$AI$1)),祝日!$A$2:$A$200)))+IF(O6="",0,MAX(0,NETWORKDAYS(O6,IF(P6<>"",P6,IF($J6<>"",O6,$AI$1)),祝日!$A$2:$A$200)))+IF(Q6="",0,MAX(0,NETWORKDAYS(Q6,IF(R6<>"",R6,IF($J6<>"",Q6,$AI$1)),祝日!$A$2:$A$200)))+IF(S6="",0,MAX(0,NETWORKDAYS(S6,IF(T6<>"",T6,IF($J6<>"",S6,$AI$1)),祝日!$A$2:$A$200)))+IF(U6="",0,MAX(0,NETWORKDAYS(U6,IF(V6<>"",V6,IF($J6<>"",U6,$AI$1)),祝日!$A$2:$A$200)))+IF(W6="",0,MAX(0,NETWORKDAYS(W6,IF(X6<>"",X6,IF($J6<>"",W6,$AI$1)),祝日!$A$2:$A$200)))+IF(Y6="",0,MAX(0,NETWORKDAYS(Y6,IF(Z6<>"",Z6,IF($J6<>"",Y6,$AI$1)),祝日!$A$2:$A$200)))+IF(AA6="",0,MAX(0,NETWORKDAYS(AA6,IF(AB6<>"",AB6,IF($J6<>"",AA6,$AI$1)),祝日!$A$2:$A$200)))+IF(AC6="",0,MAX(0,NETWORKDAYS(AC6,IF(AD6<>"",AD6,IF($J6<>"",AC6,$AI$1)),祝日!$A$2:$A$200)))+IF(AE6="",0,MAX(0,NETWORKDAYS(AE6,IF(AF6<>"",AF6,IF($J6<>"",AE6,$AI$1)),祝日!$A$2:$A$200)))+IF(AG6="",0,MAX(0,NETWORKDAYS(AG6,IF(AH6<>"",AH6,IF($J6<>"",AG6,$AI$1)),祝日!$A$2:$A$200)))) | F6: =IF($D6="","",$D6-$E6) | G6: =IF(OR($D6="",$D6=0),"",$E6/$D6) | H6: =IF($D6="","",IF($J6<>"","FIX",IF(AND(SUMPRODUCT((MOD(COLUMN($K6:$AH6)-COLUMN($K6),2)=0)*($K6:$AH6<>""))=0,SUMPRODUCT((MOD(COLUMN($K6:$AH6)-COLUMN($K6),2)=1)*($K6:$AH6<>""))=0),"未着手",IF(SUMPRODUCT((MOD(COLUMN($K6:$AH6)-COLUMN($K6),2)=0)*($K6:$AH6<>""))>SUMPRODUCT((MOD(COLUMN($K6:$AH6)-COLUMN($K6),2)=1)*($K6:$AH6<>"")),"作業中","中断")))) | I6: =IF($H6="中断",MAX(0,$AI$1-MAX(L6,N6,P6,R6,T6,V6,X6,Z6,AB6,AD6,AF6,AH6)),"") | AK6: =IF($A4="","",IF(LOOKUP(2,1/($AJ$3:$AJ6<>""),$AJ$3:$AJ6)="-","",LOOKUP(2,1/($AJ$3:$AJ6<>""),$AJ$3:$AJ6))) | AL6: =$H6 | AM6: =IF(ISNUMBER($D6),$D6,0) -> 0 | AN6: =IF(ISNUMBER($E6),$E6,0) -> 0 | AO6: =IF(ISNUMBER($F6),$F6,0) -> 0 | AQ6: =IF(OR($AK6="",K6="",L6=""),0,COUNTIFS($AK$3:$AK$98,$AK6,K$3:K$98,"<"&L6,L$3:L$98,">"&K6)+COUNTIFS($AK$3:$AK$98,$AK6,M$3:M$98,"<"&L6,N$3:N$98,">"&K6)+COUNTIFS($AK$3:$AK$98,$AK6,O$3:O$98,"<"&L6,P$3:P$98,">"&K6)+COUNTIFS($AK$3:$AK$98,$AK6,Q$3:Q$98,"<"&L6,R$3:R$98,">"&K6)+COUNTIFS($AK$3:$AK$98,$AK6,S$3:S$98,"<"&L6,T$3:T$98,">"&K6)+COUNTIFS($AK$3:$AK$98,$AK6,U$3:U$98,"<"&L6,V$3:V$98,">"&K6)+COUNTIFS($AK$3:$AK$98,$AK6,W$3:W$98,"<"&L6,X$3:X$98,">"&K6)+COUNTIFS($AK$3:$AK$98,$AK6,Y$3:Y$98,"<"&L6,Z$3:Z$98,">"&K6)+COUNTIFS($AK$3:$AK$98,$AK6,AA$3:AA$98,"<"&L6,AB$3:AB$98,">"&K6)+COUNTIFS($AK$3:$AK$98,$AK6,AC$3:AC$98,"<"&L6,AD$3:AD$98,">"&K6)+COUNTIFS($AK$3:$AK$98,$AK6,AE$3:AE$98,"<"&L6,AF$3:AF$98,">"&K6)+COUNTIFS($AK$3:$AK$98,$AK6,AG$3:AG$98,"<"&L6,AH$3:AH$98,">"&K6)-(K6<L6)) -> 0 | AR6: =AQ6 -> 0 | AS6: =IF(OR($AK6="",M6="",N6=""),0,COUNTIFS($AK$3:$AK$98,$AK6,K$3:K$98,"<"&N6,L$3:L$98,">"&M6)+COUNTIFS($AK$3:$AK$98,$AK6,M$3:M$98,"<"&N6,N$3:N$98,">"&M6)+COUNTIFS($AK$3:$AK$98,$AK6,O$3:O$98,"<"&N6,P$3:P$98,">"&M6)+COUNTIFS($AK$3:$AK$98,$AK6,Q$3:Q$98,"<"&N6,R$3:R$98,">"&M6)+COUNTIFS($AK$3:$AK$98,$AK6,S$3:S$98,"<"&N6,T$3:T$98,">"&M6)+COUNTIFS($AK$3:$AK$98,$AK6,U$3:U$98,"<"&N6,V$3:V$98,">"&M6)+COUNTIFS($AK$3:$AK$98,$AK6,W$3:W$98,"<"&N6,X$3:X$98,">"&M6)+COUNTIFS($AK$3:$AK$98,$AK6,Y$3:Y$98,"<"&N6,Z$3:Z$98,">"&M6)+COUNTIFS($AK$3:$AK$98,$AK6,AA$3:AA$98,"<"&N6,AB$3:AB$98,">"&M6)+COUNTIFS($AK$3:$AK$98,$AK6,AC$3:AC$98,"<"&N6,AD$3:AD$98,">"&M6)+COUNTIFS($AK$3:$AK$98,$AK6,AE$3:AE$98,"<"&N6,AF$3:AF$98,">"&M6)+COUNTIFS($AK$3:$AK$98,$AK6,AG$3:AG$98,"<"&N6,AH$3:AH$98,">"&M6)-(M6<N6)) -> 0 | AT6: =AS6 -> 0 | AU6: =IF(OR($AK6="",O6="",P6=""),0,COUNTIFS($AK$3:$AK$98,$AK6,K$3:K$98,"<"&P6,L$3:L$98,">"&O6)+COUNTIFS($AK$3:$AK$98,$AK6,M$3:M$98,"<"&P6,N$3:N$98,">"&O6)+COUNTIFS($AK$3:$AK$98,$AK6,O$3:O$98,"<"&P6,P$3:P$98,">"&O6)+COUNTIFS($AK$3:$AK$98,$AK6,Q$3:Q$98,"<"&P6,R$3:R$98,">"&O6)+COUNTIFS($AK$3:$AK$98,$AK6,S$3:S$98,"<"&P6,T$3:T$98,">"&O6)+COUNTIFS($AK$3:$AK$98,$AK6,U$3:U$98,"<"&P6,V$3:V$98,">"&O6)+COUNTIFS($AK$3:$AK$98,$AK6,W$3:W$98,"<"&P6,X$3:X$98,">"&O6)+COUNTIFS($AK$3:$AK$98,$AK6,Y$3:Y$98,"<"&P6,Z$3:Z$98,">"&O6)+COUNTIFS($AK$3:$AK$98,$AK6,AA$3:AA$98,"<"&P6,AB$3:AB$98,">"&O6)+COUNTIFS($AK$3:$AK$98,$AK6,AC$3:AC$98,"<"&P6,AD$3:AD$98,">"&O6)+COUNTIFS($AK$3:$AK$98,$AK6,AE$3:AE$98,"<"&P6,AF$3:AF$98,">"&O6)+COUNTIFS($AK$3:$AK$98,$AK6,AG$3:AG$98,"<"&P6,AH$3:AH$98,">"&O6)-(O6<P6)) -> 0 | AV6: =AU6 -> 0 | AW6: =IF(OR($AK6="",Q6="",R6=""),0,COUNTIFS($AK$3:$AK$98,$AK6,K$3:K$98,"<"&R6,L$3:L$98,">"&Q6)+COUNTIFS($AK$3:$AK$98,$AK6,M$3:M$98,"<"&R6,N$3:N$98,">"&Q6)+COUNTIFS($AK$3:$AK$98,$AK6,O$3:O$98,"<"&R6,P$3:P$98,">"&Q6)+COUNTIFS($AK$3:$AK$98,$AK6,Q$3:Q$98,"<"&R6,R$3:R$98,">"&Q6)+COUNTIFS($AK$3:$AK$98,$AK6,S$3:S$98,"<"&R6,T$3:T$98,">"&Q6)+COUNTIFS($AK$3:$AK$98,$AK6,U$3:U$98,"<"&R6,V$3:V$98,">"&Q6)+COUNTIFS($AK$3:$AK$98,$AK6,W$3:W$98,"<"&R6,X$3:X$98,">"&Q6)+COUNTIFS($AK$3:$AK$98,$AK6,Y$3:Y$98,"<"&R6,Z$3:Z$98,">"&Q6)+COUNTIFS($AK$3:$AK$98,$AK6,AA$3:AA$98,"<"&R6,AB$3:AB$98,">"&Q6)+COUNTIFS($AK$3:$AK$98,$AK6,AC$3:AC$98,"<"&R6,AD$3:AD$98,">"&Q6)+COUNTIFS($AK$3:$AK$98,$AK6,AE$3:AE$98,"<"&R6,AF$3:AF$98,">"&Q6)+COUNTIFS($AK$3:$AK$98,$AK6,AG$3:AG$98,"<"&R6,AH$3:AH$98,">"&Q6)-(Q6<R6)) -> 0 | AX6: =AW6 -> 0 | AY6: =IF(OR($AK6="",S6="",T6=""),0,COUNTIFS($AK$3:$AK$98,$AK6,K$3:K$98,"<"&T6,L$3:L$98,">"&S6)+COUNTIFS($AK$3:$AK$98,$AK6,M$3:M$98,"<"&T6,N$3:N$98,">"&S6)+COUNTIFS($AK$3:$AK$98,$AK6,O$3:O$98,"<"&T6,P$3:P$98,">"&S6)+COUNTIFS($AK$3:$AK$98,$AK6,Q$3:Q$98,"<"&T6,R$3:R$98,">"&S6)+COUNTIFS($AK$3:$AK$98,$AK6,S$3:S$98,"<"&T6,T$3:T$98,">"&S6)+COUNTIFS($AK$3:$AK$98,$AK6,U$3:U$98,"<"&T6,V$3:V$98,">"&S6)+COUNTIFS($AK$3:$AK$98,$AK6,W$3:W$98,"<"&T6,X$3:X$98,">"&S6)+COUNTIFS($AK$3:$AK$98,$AK6,Y$3:Y$98,"<"&T6,Z$3:Z$98,">"&S6)+COUNTIFS($AK$3:$AK$98,$AK6,AA$3:AA$98,"<"&T6,AB$3:AB$98,">"&S6)+COUNTIFS($AK$3:$AK$98,$AK6,AC$3:AC$98,"<"&T6,AD$3:AD$98,">"&S6)+COUNTIFS($AK$3:$AK$98,$AK6,AE$3:AE$98,"<"&T6,AF$3:AF$98,">"&S6)+COUNTIFS($AK$3:$AK$98,$AK6,AG$3:AG$98,"<"&T6,AH$3:AH$98,">"&S6)-(S6<T6)) -> 0 | AZ6: =AY6 -> 0 | BA6: =IF(OR($AK6="",U6="",V6=""),0,COUNTIFS($AK$3:$AK$98,$AK6,K$3:K$98,"<"&V6,L$3:L$98,">"&U6)+COUNTIFS($AK$3:$AK$98,$AK6,M$3:M$98,"<"&V6,N$3:N$98,">"&U6)+COUNTIFS($AK$3:$AK$98,$AK6,O$3:O$98,"<"&V6,P$3:P$98,">"&U6)+COUNTIFS($AK$3:$AK$98,$AK6,Q$3:Q$98,"<"&V6,R$3:R$98,">"&U6)+COUNTIFS($AK$3:$AK$98,$AK6,S$3:S$98,"<"&V6,T$3:T$98,">"&U6)+COUNTIFS($AK$3:$AK$98,$AK6,U$3:U$98,"<"&V6,V$3:V$98,">"&U6)+COUNTIFS($AK$3:$AK$98,$AK6,W$3:W$98,"<"&V6,X$3:X$98,">"&U6)+COUNTIFS($AK$3:$AK$98,$AK6,Y$3:Y$98,"<"&V6,Z$3:Z$98,">"&U6)+COUNTIFS($AK$3:$AK$98,$AK6,AA$3:AA$98,"<"&V6,AB$3:AB$98,">"&U6)+COUNTIFS($AK$3:$AK$98,$AK6,AC$3:AC$98,"<"&V6,AD$3:AD$98,">"&U6)+COUNTIFS($AK$3:$AK$98,$AK6,AE$3:AE$98,"<"&V6,AF$3:AF$98,">"&U6)+COUNTIFS($AK$3:$AK$98,$AK6,AG$3:AG$98,"<"&V6,AH$3:AH$98,">"&U6)-(U6<V6)) -> 0 | BB6: =BA6 -> 0 | BC6: =IF(OR($AK6="",W6="",X6=""),0,COUNTIFS($AK$3:$AK$98,$AK6,K$3:K$98,"<"&X6,L$3:L$98,">"&W6)+COUNTIFS($AK$3:$AK$98,$AK6,M$3:M$98,"<"&X6,N$3:N$98,">"&W6)+COUNTIFS($AK$3:$AK$98,$AK6,O$3:O$98,"<"&X6,P$3:P$98,">"&W6)+COUNTIFS($AK$3:$AK$98,$AK6,Q$3:Q$98,"<"&X6,R$3:R$98,">"&W6)+COUNTIFS($AK$3:$AK$98,$AK6,S$3:S$98,"<"&X6,T$3:T$98,">"&W6)+COUNTIFS($AK$3:$AK$98,$AK6,U$3:U$98,"<"&X6,V$3:V$98,">"&W6)+COUNTIFS($AK$3:$AK$98,$AK6,W$3:W$98,"<"&X6,X$3:X$98,">"&W6)+COUNTIFS($AK$3:$AK$98,$AK6,Y$3:Y$98,"<"&X6,Z$3:Z$98,">"&W6)+COUNTIFS($AK$3:$AK$98,$AK6,AA$3:AA$98,"<"&X6,AB$3:AB$98,">"&W6)+COUNTIFS($AK$3:$AK$98,$AK6,AC$3:AC$98,"<"&X6,AD$3:AD$98,">"&W6)+COUNTIFS($AK$3:$AK$98,$AK6,AE$3:AE$98,"<"&X6,AF$3:AF$98,">"&W6)+COUNTIFS($AK$3:$AK$98,$AK6,AG$3:AG$98,"<"&X6,AH$3:AH$98,">"&W6)-(W6<X6)) -> 0 | BD6: =BC6 -> 0 | BE6: =IF(OR($AK6="",Y6="",Z6=""),0,COUNTIFS($AK$3:$AK$98,$AK6,K$3:K$98,"<"&Z6,L$3:L$98,">"&Y6)+COUNTIFS($AK$3:$AK$98,$AK6,M$3:M$98,"<"&Z6,N$3:N$98,">"&Y6)+COUNTIFS($AK$3:$AK$98,$AK6,O$3:O$98,"<"&Z6,P$3:P$98,">"&Y6)+COUNTIFS($AK$3:$AK$98,$AK6,Q$3:Q$98,"<"&Z6,R$3:R$98,">"&Y6)+COUNTIFS($AK$3:$AK$98,$AK6,S$3:S$98,"<"&Z6,T$3:T$98,">"&Y6)+COUNTIFS($AK$3:$AK$98,$AK6,U$3:U$98,"<"&Z6,V$3:V$98,">"&Y6)+COUNTIFS($AK$3:$AK$98,$AK6,W$3:W$98,"<"&Z6,X$3:X$98,">"&Y6)+COUNTIFS($AK$3:$AK$98,$AK6,Y$3:Y$98,"<"&Z6,Z$3:Z$98,">"&Y6)+COUNTIFS($AK$3:$AK$98,$AK6,AA$3:AA$98,"<"&Z6,AB$3:AB$98,">"&Y6)+COUNTIFS($AK$3:$AK$98,$AK6,AC$3:AC$98,"<"&Z6,AD$3:AD$98,">"&Y6)+COUNTIFS($AK$3:$AK$98,$AK6,AE$3:AE$98,"<"&Z6,AF$3:AF$98,">"&Y6)+COUNTIFS($AK$3:$AK$98,$AK6,AG$3:AG$98,"<"&Z6,AH$3:AH$98,">"&Y6)-(Y6<Z6)) -> 0 | BF6: =BE6 -> 0 | BG6: =IF(OR($AK6="",AA6="",AB6=""),0,COUNTIFS($AK$3:$AK$98,$AK6,K$3:K$98,"<"&AB6,L$3:L$98,">"&AA6)+COUNTIFS($AK$3:$AK$98,$AK6,M$3:M$98,"<"&AB6,N$3:N$98,">"&AA6)+COUNTIFS($AK$3:$AK$98,$AK6,O$3:O$98,"<"&AB6,P$3:P$98,">"&AA6)+COUNTIFS($AK$3:$AK$98,$AK6,Q$3:Q$98,"<"&AB6,R$3:R$98,">"&AA6)+COUNTIFS($AK$3:$AK$98,$AK6,S$3:S$98,"<"&AB6,T$3:T$98,">"&AA6)+COUNTIFS($AK$3:$AK$98,$AK6,U$3:U$98,"<"&AB6,V$3:V$98,">"&AA6)+COUNTIFS($AK$3:$AK$98,$AK6,W$3:W$98,"<"&AB6,X$3:X$98,">"&AA6)+COUNTIFS($AK$3:$AK$98,$AK6,Y$3:Y$98,"<"&AB6,Z$3:Z$98,">"&AA6)+COUNTIFS($AK$3:$AK$98,$AK6,AA$3:AA$98,"<"&AB6,AB$3:AB$98,">"&AA6)+COUNTIFS($AK$3:$AK$98,$AK6,AC$3:AC$98,"<"&AB6,AD$3:AD$98,">"&AA6)+COUNTIFS($AK$3:$AK$98,$AK6,AE$3:AE$98,"<"&AB6,AF$3:AF$98,">"&AA6)+COUNTIFS($AK$3:$AK$98,$AK6,AG$3:AG$98,"<"&AB6,AH$3:AH$98,">"&AA6)-(AA6<AB6)) -> 0 | BH6: =BG6 -> 0 | BI6: =IF(OR($AK6="",AC6="",AD6=""),0,COUNTIFS($AK$3:$AK$98,$AK6,K$3:K$98,"<"&AD6,L$3:L$98,">"&AC6)+COUNTIFS($AK$3:$AK$98,$AK6,M$3:M$98,"<"&AD6,N$3:N$98,">"&AC6)+COUNTIFS($AK$3:$AK$98,$AK6,O$3:O$98,"<"&AD6,P$3:P$98,">"&AC6)+COUNTIFS($AK$3:$AK$98,$AK6,Q$3:Q$98,"<"&AD6,R$3:R$98,">"&AC6)+COUNTIFS($AK$3:$AK$98,$AK6,S$3:S$98,"<"&AD6,T$3:T$98,">"&AC6)+COUNTIFS($AK$3:$AK$98,$AK6,U$3:U$98,"<"&AD6,V$3:V$98,">"&AC6)+COUNTIFS($AK$3:$AK$98,$AK6,W$3:W$98,"<"&AD6,X$3:X$98,">"&AC6)+COUNTIFS($AK$3:$AK$98,$AK6,Y$3:Y$98,"<"&AD6,Z$3:Z$98,">"&AC6)+COUNTIFS($AK$3:$AK$98,$AK6,AA$3:AA$98,"<"&AD6,AB$3:AB$98,">"&AC6)+COUNTIFS($AK$3:$AK$98,$AK6,AC$3:AC$98,"<"&AD6,AD$3:AD$98,">"&AC6)+COUNTIFS($AK$3:$AK$98,$AK6,AE$3:AE$98,"<"&AD6,AF$3:AF$98,">"&AC6)+COUNTIFS($AK$3:$AK$98,$AK6,AG$3:AG$98,"<"&AD6,AH$3:AH$98,">"&AC6)-(AC6<AD6)) -> 0 | BJ6: =BI6 -> 0 | BK6: =IF(OR($AK6="",AE6="",AF6=""),0,COUNTIFS($AK$3:$AK$98,$AK6,K$3:K$98,"<"&AF6,L$3:L$98,">"&AE6)+COUNTIFS($AK$3:$AK$98,$AK6,M$3:M$98,"<"&AF6,N$3:N$98,">"&AE6)+COUNTIFS($AK$3:$AK$98,$AK6,O$3:O$98,"<"&AF6,P$3:P$98,">"&AE6)+COUNTIFS($AK$3:$AK$98,$AK6,Q$3:Q$98,"<"&AF6,R$3:R$98,">"&AE6)+COUNTIFS($AK$3:$AK$98,$AK6,S$3:S$98,"<"&AF6,T$3:T$98,">"&AE6)+COUNTIFS($AK$3:$AK$98,$AK6,U$3:U$98,"<"&AF6,V$3:V$98,">"&AE6)+COUNTIFS($AK$3:$AK$98,$AK6,W$3:W$98,"<"&AF6,X$3:X$98,">"&AE6)+COUNTIFS($AK$3:$AK$98,$AK6,Y$3:Y$98,"<"&AF6,Z$3:Z$98,">"&AE6)+COUNTIFS($AK$3:$AK$98,$AK6,AA$3:AA$98,"<"&AF6,AB$3:AB$98,">"&AE6)+COUNTIFS($AK$3:$AK$98,$AK6,AC$3:AC$98,"<"&AF6,AD$3:AD$98,">"&AE6)+COUNTIFS($AK$3:$AK$98,$AK6,AE$3:AE$98,"<"&AF6,AF$3:AF$98,">"&AE6)+COUNTIFS($AK$3:$AK$98,$AK6,AG$3:AG$98,"<"&AF6,AH$3:AH$98,">"&AE6)-(AE6<AF6)) -> 0 | BL6: =BK6 -> 0 | BM6: =IF(OR($AK6="",AG6="",AH6=""),0,COUNTIFS($AK$3:$AK$98,$AK6,K$3:K$98,"<"&AH6,L$3:L$98,">"&AG6)+COUNTIFS($AK$3:$AK$98,$AK6,M$3:M$98,"<"&AH6,N$3:N$98,">"&AG6)+COUNTIFS($AK$3:$AK$98,$AK6,O$3:O$98,"<"&AH6,P$3:P$98,">"&AG6)+COUNTIFS($AK$3:$AK$98,$AK6,Q$3:Q$98,"<"&AH6,R$3:R$98,">"&AG6)+COUNTIFS($AK$3:$AK$98,$AK6,S$3:S$98,"<"&AH6,T$3:T$98,">"&AG6)+COUNTIFS($AK$3:$AK$98,$AK6,U$3:U$98,"<"&AH6,V$3:V$98,">"&AG6)+COUNTIFS($AK$3:$AK$98,$AK6,W$3:W$98,"<"&AH6,X$3:X$98,">"&AG6)+COUNTIFS($AK$3:$AK$98,$AK6,Y$3:Y$98,"<"&AH6,Z$3:Z$98,">"&AG6)+COUNTIFS($AK$3:$AK$98,$AK6,AA$3:AA$98,"<"&AH6,AB$3:AB$98,">"&AG6)+COUNTIFS($AK$3:$AK$98,$AK6,AC$3:AC$98,"<"&AH6,AD$3:AD$98,">"&AG6)+COUNTIFS($AK$3:$AK$98,$AK6,AE$3:AE$98,"<"&AH6,AF$3:AF$98,">"&AG6)+COUNTIFS($AK$3:$AK$98,$AK6,AG$3:AG$98,"<"&AH6,AH$3:AH$98,">"&AG6)-(AG6<AH6)) -> 0 | BN6: =BM6 -> 0 | BO6: =IF(ISNUMBER($G6),$G6,"") | BP6: =IF(AND($A6<>"",COUNT($K6:$AH6)>0),ROW(),"")
A7: =IF($A4="","",$A4) | B7: =IF($A4="","","fac") | E7: =IF(AND($D7="",COUNT($K7:$AH7)=0),"",IF(K7="",0,MAX(0,NETWORKDAYS(K7,IF(L7<>"",L7,IF($J7<>"",K7,$AI$1)),祝日!$A$2:$A$200)))+IF(M7="",0,MAX(0,NETWORKDAYS(M7,IF(N7<>"",N7,IF($J7<>"",M7,$AI$1)),祝日!$A$2:$A$200)))+IF(O7="",0,MAX(0,NETWORKDAYS(O7,IF(P7<>"",P7,IF($J7<>"",O7,$AI$1)),祝日!$A$2:$A$200)))+IF(Q7="",0,MAX(0,NETWORKDAYS(Q7,IF(R7<>"",R7,IF($J7<>"",Q7,$AI$1)),祝日!$A$2:$A$200)))+IF(S7="",0,MAX(0,NETWORKDAYS(S7,IF(T7<>"",T7,IF($J7<>"",S7,$AI$1)),祝日!$A$2:$A$200)))+IF(U7="",0,MAX(0,NETWORKDAYS(U7,IF(V7<>"",V7,IF($J7<>"",U7,$AI$1)),祝日!$A$2:$A$200)))+IF(W7="",0,MAX(0,NETWORKDAYS(W7,IF(X7<>"",X7,IF($J7<>"",W7,$AI$1)),祝日!$A$2:$A$200)))+IF(Y7="",0,MAX(0,NETWORKDAYS(Y7,IF(Z7<>"",Z7,IF($J7<>"",Y7,$AI$1)),祝日!$A$2:$A$200)))+IF(AA7="",0,MAX(0,NETWORKDAYS(AA7,IF(AB7<>"",AB7,IF($J7<>"",AA7,$AI$1)),祝日!$A$2:$A$200)))+IF(AC7="",0,MAX(0,NETWORKDAYS(AC7,IF(AD7<>"",AD7,IF($J7<>"",AC7,$AI$1)),祝日!$A$2:$A$200)))+IF(AE7="",0,MAX(0,NETWORKDAYS(AE7,IF(AF7<>"",AF7,IF($J7<>"",AE7,$AI$1)),祝日!$A$2:$A$200)))+IF(AG7="",0,MAX(0,NETWORKDAYS(AG7,IF(AH7<>"",AH7,IF($J7<>"",AG7,$AI$1)),祝日!$A$2:$A$200)))) | F7: =IF($D7="","",$D7-$E7) | G7: =IF(OR($D7="",$D7=0),"",$E7/$D7) | H7: =IF($D7="","",IF($J7<>"","FIX",IF(AND(SUMPRODUCT((MOD(COLUMN($K7:$AH7)-COLUMN($K7),2)=0)*($K7:$AH7<>""))=0,SUMPRODUCT((MOD(COLUMN($K7:$AH7)-COLUMN($K7),2)=1)*($K7:$AH7<>""))=0),"未着手",IF(SUMPRODUCT((MOD(COLUMN($K7:$AH7)-COLUMN($K7),2)=0)*($K7:$AH7<>""))>SUMPRODUCT((MOD(COLUMN($K7:$AH7)-COLUMN($K7),2)=1)*($K7:$AH7<>"")),"作業中","中断")))) | I7: =IF($H7="中断",MAX(0,$AI$1-MAX(L7,N7,P7,R7,T7,V7,X7,Z7,AB7,AD7,AF7,AH7)),"") | AK7: =IF($A4="","",IF(LOOKUP(2,1/($AJ$3:$AJ7<>""),$AJ$3:$AJ7)="-","",LOOKUP(2,1/($AJ$3:$AJ7<>""),$AJ$3:$AJ7))) | AL7: =$H7 | AM7: =IF(ISNUMBER($D7),$D7,0) -> 0 | AN7: =IF(ISNUMBER($E7),$E7,0) -> 0 | AO7: =IF(ISNUMBER($F7),$F7,0) -> 0 | AQ7: =IF(OR($AK7="",K7="",L7=""),0,COUNTIFS($AK$3:$AK$98,$AK7,K$3:K$98,"<"&L7,L$3:L$98,">"&K7)+COUNTIFS($AK$3:$AK$98,$AK7,M$3:M$98,"<"&L7,N$3:N$98,">"&K7)+COUNTIFS($AK$3:$AK$98,$AK7,O$3:O$98,"<"&L7,P$3:P$98,">"&K7)+COUNTIFS($AK$3:$AK$98,$AK7,Q$3:Q$98,"<"&L7,R$3:R$98,">"&K7)+COUNTIFS($AK$3:$AK$98,$AK7,S$3:S$98,"<"&L7,T$3:T$98,">"&K7)+COUNTIFS($AK$3:$AK$98,$AK7,U$3:U$98,"<"&L7,V$3:V$98,">"&K7)+COUNTIFS($AK$3:$AK$98,$AK7,W$3:W$98,"<"&L7,X$3:X$98,">"&K7)+COUNTIFS($AK$3:$AK$98,$AK7,Y$3:Y$98,"<"&L7,Z$3:Z$98,">"&K7)+COUNTIFS($AK$3:$AK$98,$AK7,AA$3:AA$98,"<"&L7,AB$3:AB$98,">"&K7)+COUNTIFS($AK$3:$AK$98,$AK7,AC$3:AC$98,"<"&L7,AD$3:AD$98,">"&K7)+COUNTIFS($AK$3:$AK$98,$AK7,AE$3:AE$98,"<"&L7,AF$3:AF$98,">"&K7)+COUNTIFS($AK$3:$AK$98,$AK7,AG$3:AG$98,"<"&L7,AH$3:AH$98,">"&K7)-(K7<L7)) -> 0 | AR7: =AQ7 -> 0 | AS7: =IF(OR($AK7="",M7="",N7=""),0,COUNTIFS($AK$3:$AK$98,$AK7,K$3:K$98,"<"&N7,L$3:L$98,">"&M7)+COUNTIFS($AK$3:$AK$98,$AK7,M$3:M$98,"<"&N7,N$3:N$98,">"&M7)+COUNTIFS($AK$3:$AK$98,$AK7,O$3:O$98,"<"&N7,P$3:P$98,">"&M7)+COUNTIFS($AK$3:$AK$98,$AK7,Q$3:Q$98,"<"&N7,R$3:R$98,">"&M7)+COUNTIFS($AK$3:$AK$98,$AK7,S$3:S$98,"<"&N7,T$3:T$98,">"&M7)+COUNTIFS($AK$3:$AK$98,$AK7,U$3:U$98,"<"&N7,V$3:V$98,">"&M7)+COUNTIFS($AK$3:$AK$98,$AK7,W$3:W$98,"<"&N7,X$3:X$98,">"&M7)+COUNTIFS($AK$3:$AK$98,$AK7,Y$3:Y$98,"<"&N7,Z$3:Z$98,">"&M7)+COUNTIFS($AK$3:$AK$98,$AK7,AA$3:AA$98,"<"&N7,AB$3:AB$98,">"&M7)+COUNTIFS($AK$3:$AK$98,$AK7,AC$3:AC$98,"<"&N7,AD$3:AD$98,">"&M7)+COUNTIFS($AK$3:$AK$98,$AK7,AE$3:AE$98,"<"&N7,AF$3:AF$98,">"&M7)+COUNTIFS($AK$3:$AK$98,$AK7,AG$3:AG$98,"<"&N7,AH$3:AH$98,">"&M7)-(M7<N7)) -> 0 | AT7: =AS7 -> 0 | AU7: =IF(OR($AK7="",O7="",P7=""),0,COUNTIFS($AK$3:$AK$98,$AK7,K$3:K$98,"<"&P7,L$3:L$98,">"&O7)+COUNTIFS($AK$3:$AK$98,$AK7,M$3:M$98,"<"&P7,N$3:N$98,">"&O7)+COUNTIFS($AK$3:$AK$98,$AK7,O$3:O$98,"<"&P7,P$3:P$98,">"&O7)+COUNTIFS($AK$3:$AK$98,$AK7,Q$3:Q$98,"<"&P7,R$3:R$98,">"&O7)+COUNTIFS($AK$3:$AK$98,$AK7,S$3:S$98,"<"&P7,T$3:T$98,">"&O7)+COUNTIFS($AK$3:$AK$98,$AK7,U$3:U$98,"<"&P7,V$3:V$98,">"&O7)+COUNTIFS($AK$3:$AK$98,$AK7,W$3:W$98,"<"&P7,X$3:X$98,">"&O7)+COUNTIFS($AK$3:$AK$98,$AK7,Y$3:Y$98,"<"&P7,Z$3:Z$98,">"&O7)+COUNTIFS($AK$3:$AK$98,$AK7,AA$3:AA$98,"<"&P7,AB$3:AB$98,">"&O7)+COUNTIFS($AK$3:$AK$98,$AK7,AC$3:AC$98,"<"&P7,AD$3:AD$98,">"&O7)+COUNTIFS($AK$3:$AK$98,$AK7,AE$3:AE$98,"<"&P7,AF$3:AF$98,">"&O7)+COUNTIFS($AK$3:$AK$98,$AK7,AG$3:AG$98,"<"&P7,AH$3:AH$98,">"&O7)-(O7<P7)) -> 0 | AV7: =AU7 -> 0 | AW7: =IF(OR($AK7="",Q7="",R7=""),0,COUNTIFS($AK$3:$AK$98,$AK7,K$3:K$98,"<"&R7,L$3:L$98,">"&Q7)+COUNTIFS($AK$3:$AK$98,$AK7,M$3:M$98,"<"&R7,N$3:N$98,">"&Q7)+COUNTIFS($AK$3:$AK$98,$AK7,O$3:O$98,"<"&R7,P$3:P$98,">"&Q7)+COUNTIFS($AK$3:$AK$98,$AK7,Q$3:Q$98,"<"&R7,R$3:R$98,">"&Q7)+COUNTIFS($AK$3:$AK$98,$AK7,S$3:S$98,"<"&R7,T$3:T$98,">"&Q7)+COUNTIFS($AK$3:$AK$98,$AK7,U$3:U$98,"<"&R7,V$3:V$98,">"&Q7)+COUNTIFS($AK$3:$AK$98,$AK7,W$3:W$98,"<"&R7,X$3:X$98,">"&Q7)+COUNTIFS($AK$3:$AK$98,$AK7,Y$3:Y$98,"<"&R7,Z$3:Z$98,">"&Q7)+COUNTIFS($AK$3:$AK$98,$AK7,AA$3:AA$98,"<"&R7,AB$3:AB$98,">"&Q7)+COUNTIFS($AK$3:$AK$98,$AK7,AC$3:AC$98,"<"&R7,AD$3:AD$98,">"&Q7)+COUNTIFS($AK$3:$AK$98,$AK7,AE$3:AE$98,"<"&R7,AF$3:AF$98,">"&Q7)+COUNTIFS($AK$3:$AK$98,$AK7,AG$3:AG$98,"<"&R7,AH$3:AH$98,">"&Q7)-(Q7<R7)) -> 0 | AX7: =AW7 -> 0 | AY7: =IF(OR($AK7="",S7="",T7=""),0,COUNTIFS($AK$3:$AK$98,$AK7,K$3:K$98,"<"&T7,L$3:L$98,">"&S7)+COUNTIFS($AK$3:$AK$98,$AK7,M$3:M$98,"<"&T7,N$3:N$98,">"&S7)+COUNTIFS($AK$3:$AK$98,$AK7,O$3:O$98,"<"&T7,P$3:P$98,">"&S7)+COUNTIFS($AK$3:$AK$98,$AK7,Q$3:Q$98,"<"&T7,R$3:R$98,">"&S7)+COUNTIFS($AK$3:$AK$98,$AK7,S$3:S$98,"<"&T7,T$3:T$98,">"&S7)+COUNTIFS($AK$3:$AK$98,$AK7,U$3:U$98,"<"&T7,V$3:V$98,">"&S7)+COUNTIFS($AK$3:$AK$98,$AK7,W$3:W$98,"<"&T7,X$3:X$98,">"&S7)+COUNTIFS($AK$3:$AK$98,$AK7,Y$3:Y$98,"<"&T7,Z$3:Z$98,">"&S7)+COUNTIFS($AK$3:$AK$98,$AK7,AA$3:AA$98,"<"&T7,AB$3:AB$98,">"&S7)+COUNTIFS($AK$3:$AK$98,$AK7,AC$3:AC$98,"<"&T7,AD$3:AD$98,">"&S7)+COUNTIFS($AK$3:$AK$98,$AK7,AE$3:AE$98,"<"&T7,AF$3:AF$98,">"&S7)+COUNTIFS($AK$3:$AK$98,$AK7,AG$3:AG$98,"<"&T7,AH$3:AH$98,">"&S7)-(S7<T7)) -> 0 | AZ7: =AY7 -> 0 | BA7: =IF(OR($AK7="",U7="",V7=""),0,COUNTIFS($AK$3:$AK$98,$AK7,K$3:K$98,"<"&V7,L$3:L$98,">"&U7)+COUNTIFS($AK$3:$AK$98,$AK7,M$3:M$98,"<"&V7,N$3:N$98,">"&U7)+COUNTIFS($AK$3:$AK$98,$AK7,O$3:O$98,"<"&V7,P$3:P$98,">"&U7)+COUNTIFS($AK$3:$AK$98,$AK7,Q$3:Q$98,"<"&V7,R$3:R$98,">"&U7)+COUNTIFS($AK$3:$AK$98,$AK7,S$3:S$98,"<"&V7,T$3:T$98,">"&U7)+COUNTIFS($AK$3:$AK$98,$AK7,U$3:U$98,"<"&V7,V$3:V$98,">"&U7)+COUNTIFS($AK$3:$AK$98,$AK7,W$3:W$98,"<"&V7,X$3:X$98,">"&U7)+COUNTIFS($AK$3:$AK$98,$AK7,Y$3:Y$98,"<"&V7,Z$3:Z$98,">"&U7)+COUNTIFS($AK$3:$AK$98,$AK7,AA$3:AA$98,"<"&V7,AB$3:AB$98,">"&U7)+COUNTIFS($AK$3:$AK$98,$AK7,AC$3:AC$98,"<"&V7,AD$3:AD$98,">"&U7)+COUNTIFS($AK$3:$AK$98,$AK7,AE$3:AE$98,"<"&V7,AF$3:AF$98,">"&U7)+COUNTIFS($AK$3:$AK$98,$AK7,AG$3:AG$98,"<"&V7,AH$3:AH$98,">"&U7)-(U7<V7)) -> 0 | BB7: =BA7 -> 0 | BC7: =IF(OR($AK7="",W7="",X7=""),0,COUNTIFS($AK$3:$AK$98,$AK7,K$3:K$98,"<"&X7,L$3:L$98,">"&W7)+COUNTIFS($AK$3:$AK$98,$AK7,M$3:M$98,"<"&X7,N$3:N$98,">"&W7)+COUNTIFS($AK$3:$AK$98,$AK7,O$3:O$98,"<"&X7,P$3:P$98,">"&W7)+COUNTIFS($AK$3:$AK$98,$AK7,Q$3:Q$98,"<"&X7,R$3:R$98,">"&W7)+COUNTIFS($AK$3:$AK$98,$AK7,S$3:S$98,"<"&X7,T$3:T$98,">"&W7)+COUNTIFS($AK$3:$AK$98,$AK7,U$3:U$98,"<"&X7,V$3:V$98,">"&W7)+COUNTIFS($AK$3:$AK$98,$AK7,W$3:W$98,"<"&X7,X$3:X$98,">"&W7)+COUNTIFS($AK$3:$AK$98,$AK7,Y$3:Y$98,"<"&X7,Z$3:Z$98,">"&W7)+COUNTIFS($AK$3:$AK$98,$AK7,AA$3:AA$98,"<"&X7,AB$3:AB$98,">"&W7)+COUNTIFS($AK$3:$AK$98,$AK7,AC$3:AC$98,"<"&X7,AD$3:AD$98,">"&W7)+COUNTIFS($AK$3:$AK$98,$AK7,AE$3:AE$98,"<"&X7,AF$3:AF$98,">"&W7)+COUNTIFS($AK$3:$AK$98,$AK7,AG$3:AG$98,"<"&X7,AH$3:AH$98,">"&W7)-(W7<X7)) -> 0 | BD7: =BC7 -> 0 | BE7: =IF(OR($AK7="",Y7="",Z7=""),0,COUNTIFS($AK$3:$AK$98,$AK7,K$3:K$98,"<"&Z7,L$3:L$98,">"&Y7)+COUNTIFS($AK$3:$AK$98,$AK7,M$3:M$98,"<"&Z7,N$3:N$98,">"&Y7)+COUNTIFS($AK$3:$AK$98,$AK7,O$3:O$98,"<"&Z7,P$3:P$98,">"&Y7)+COUNTIFS($AK$3:$AK$98,$AK7,Q$3:Q$98,"<"&Z7,R$3:R$98,">"&Y7)+COUNTIFS($AK$3:$AK$98,$AK7,S$3:S$98,"<"&Z7,T$3:T$98,">"&Y7)+COUNTIFS($AK$3:$AK$98,$AK7,U$3:U$98,"<"&Z7,V$3:V$98,">"&Y7)+COUNTIFS($AK$3:$AK$98,$AK7,W$3:W$98,"<"&Z7,X$3:X$98,">"&Y7)+COUNTIFS($AK$3:$AK$98,$AK7,Y$3:Y$98,"<"&Z7,Z$3:Z$98,">"&Y7)+COUNTIFS($AK$3:$AK$98,$AK7,AA$3:AA$98,"<"&Z7,AB$3:AB$98,">"&Y7)+COUNTIFS($AK$3:$AK$98,$AK7,AC$3:AC$98,"<"&Z7,AD$3:AD$98,">"&Y7)+COUNTIFS($AK$3:$AK$98,$AK7,AE$3:AE$98,"<"&Z7,AF$3:AF$98,">"&Y7)+COUNTIFS($AK$3:$AK$98,$AK7,AG$3:AG$98,"<"&Z7,AH$3:AH$98,">"&Y7)-(Y7<Z7)) -> 0 | BF7: =BE7 -> 0 | BG7: =IF(OR($AK7="",AA7="",AB7=""),0,COUNTIFS($AK$3:$AK$98,$AK7,K$3:K$98,"<"&AB7,L$3:L$98,">"&AA7)+COUNTIFS($AK$3:$AK$98,$AK7,M$3:M$98,"<"&AB7,N$3:N$98,">"&AA7)+COUNTIFS($AK$3:$AK$98,$AK7,O$3:O$98,"<"&AB7,P$3:P$98,">"&AA7)+COUNTIFS($AK$3:$AK$98,$AK7,Q$3:Q$98,"<"&AB7,R$3:R$98,">"&AA7)+COUNTIFS($AK$3:$AK$98,$AK7,S$3:S$98,"<"&AB7,T$3:T$98,">"&AA7)+COUNTIFS($AK$3:$AK$98,$AK7,U$3:U$98,"<"&AB7,V$3:V$98,">"&AA7)+COUNTIFS($AK$3:$AK$98,$AK7,W$3:W$98,"<"&AB7,X$3:X$98,">"&AA7)+COUNTIFS($AK$3:$AK$98,$AK7,Y$3:Y$98,"<"&AB7,Z$3:Z$98,">"&AA7)+COUNTIFS($AK$3:$AK$98,$AK7,AA$3:AA$98,"<"&AB7,AB$3:AB$98,">"&AA7)+COUNTIFS($AK$3:$AK$98,$AK7,AC$3:AC$98,"<"&AB7,AD$3:AD$98,">"&AA7)+COUNTIFS($AK$3:$AK$98,$AK7,AE$3:AE$98,"<"&AB7,AF$3:AF$98,">"&AA7)+COUNTIFS($AK$3:$AK$98,$AK7,AG$3:AG$98,"<"&AB7,AH$3:AH$98,">"&AA7)-(AA7<AB7)) -> 0 | BH7: =BG7 -> 0 | BI7: =IF(OR($AK7="",AC7="",AD7=""),0,COUNTIFS($AK$3:$AK$98,$AK7,K$3:K$98,"<"&AD7,L$3:L$98,">"&AC7)+COUNTIFS($AK$3:$AK$98,$AK7,M$3:M$98,"<"&AD7,N$3:N$98,">"&AC7)+COUNTIFS($AK$3:$AK$98,$AK7,O$3:O$98,"<"&AD7,P$3:P$98,">"&AC7)+COUNTIFS($AK$3:$AK$98,$AK7,Q$3:Q$98,"<"&AD7,R$3:R$98,">"&AC7)+COUNTIFS($AK$3:$AK$98,$AK7,S$3:S$98,"<"&AD7,T$3:T$98,">"&AC7)+COUNTIFS($AK$3:$AK$98,$AK7,U$3:U$98,"<"&AD7,V$3:V$98,">"&AC7)+COUNTIFS($AK$3:$AK$98,$AK7,W$3:W$98,"<"&AD7,X$3:X$98,">"&AC7)+COUNTIFS($AK$3:$AK$98,$AK7,Y$3:Y$98,"<"&AD7,Z$3:Z$98,">"&AC7)+COUNTIFS($AK$3:$AK$98,$AK7,AA$3:AA$98,"<"&AD7,AB$3:AB$98,">"&AC7)+COUNTIFS($AK$3:$AK$98,$AK7,AC$3:AC$98,"<"&AD7,AD$3:AD$98,">"&AC7)+COUNTIFS($AK$3:$AK$98,$AK7,AE$3:AE$98,"<"&AD7,AF$3:AF$98,">"&AC7)+COUNTIFS($AK$3:$AK$98,$AK7,AG$3:AG$98,"<"&AD7,AH$3:AH$98,">"&AC7)-(AC7<AD7)) -> 0 | BJ7: =BI7 -> 0 | BK7: =IF(OR($AK7="",AE7="",AF7=""),0,COUNTIFS($AK$3:$AK$98,$AK7,K$3:K$98,"<"&AF7,L$3:L$98,">"&AE7)+COUNTIFS($AK$3:$AK$98,$AK7,M$3:M$98,"<"&AF7,N$3:N$98,">"&AE7)+COUNTIFS($AK$3:$AK$98,$AK7,O$3:O$98,"<"&AF7,P$3:P$98,">"&AE7)+COUNTIFS($AK$3:$AK$98,$AK7,Q$3:Q$98,"<"&AF7,R$3:R$98,">"&AE7)+COUNTIFS($AK$3:$AK$98,$AK7,S$3:S$98,"<"&AF7,T$3:T$98,">"&AE7)+COUNTIFS($AK$3:$AK$98,$AK7,U$3:U$98,"<"&AF7,V$3:V$98,">"&AE7)+COUNTIFS($AK$3:$AK$98,$AK7,W$3:W$98,"<"&AF7,X$3:X$98,">"&AE7)+COUNTIFS($AK$3:$AK$98,$AK7,Y$3:Y$98,"<"&AF7,Z$3:Z$98,">"&AE7)+COUNTIFS($AK$3:$AK$98,$AK7,AA$3:AA$98,"<"&AF7,AB$3:AB$98,">"&AE7)+COUNTIFS($AK$3:$AK$98,$AK7,AC$3:AC$98,"<"&AF7,AD$3:AD$98,">"&AE7)+COUNTIFS($AK$3:$AK$98,$AK7,AE$3:AE$98,"<"&AF7,AF$3:AF$98,">"&AE7)+COUNTIFS($AK$3:$AK$98,$AK7,AG$3:AG$98,"<"&AF7,AH$3:AH$98,">"&AE7)-(AE7<AF7)) -> 0 | BL7: =BK7 -> 0 | BM7: =IF(OR($AK7="",AG7="",AH7=""),0,COUNTIFS($AK$3:$AK$98,$AK7,K$3:K$98,"<"&AH7,L$3:L$98,">"&AG7)+COUNTIFS($AK$3:$AK$98,$AK7,M$3:M$98,"<"&AH7,N$3:N$98,">"&AG7)+COUNTIFS($AK$3:$AK$98,$AK7,O$3:O$98,"<"&AH7,P$3:P$98,">"&AG7)+COUNTIFS($AK$3:$AK$98,$AK7,Q$3:Q$98,"<"&AH7,R$3:R$98,">"&AG7)+COUNTIFS($AK$3:$AK$98,$AK7,S$3:S$98,"<"&AH7,T$3:T$98,">"&AG7)+COUNTIFS($AK$3:$AK$98,$AK7,U$3:U$98,"<"&AH7,V$3:V$98,">"&AG7)+COUNTIFS($AK$3:$AK$98,$AK7,W$3:W$98,"<"&AH7,X$3:X$98,">"&AG7)+COUNTIFS($AK$3:$AK$98,$AK7,Y$3:Y$98,"<"&AH7,Z$3:Z$98,">"&AG7)+COUNTIFS($AK$3:$AK$98,$AK7,AA$3:AA$98,"<"&AH7,AB$3:AB$98,">"&AG7)+COUNTIFS($AK$3:$AK$98,$AK7,AC$3:AC$98,"<"&AH7,AD$3:AD$98,">"&AG7)+COUNTIFS($AK$3:$AK$98,$AK7,AE$3:AE$98,"<"&AH7,AF$3:AF$98,">"&AG7)+COUNTIFS($AK$3:$AK$98,$AK7,AG$3:AG$98,"<"&AH7,AH$3:AH$98,">"&AG7)-(AG7<AH7)) -> 0 | BN7: =BM7 -> 0 | BO7: =IF(ISNUMBER($G7),$G7,"") | BP7: =IF(AND($A7<>"",COUNT($K7:$AH7)>0),ROW(),"")
A8: chHondawaraA | B8: =IF($A8="","","total") -> total | D8: =IF($A8="","",SUM(D9:D11)) -> 35 | E8: =IF($A8="","",SUM(E9:E11)) -> 6 | F8: =IF($A8="","",D8-E8) -> 29 | G8: =IF($A8="","",IFERROR(AVERAGEIFS(G9:G11,H9:H11,"<>未着手",H9:H11,"<>作業中"),"")) -> 0.4
A9: =IF($A8="","",$A8) -> chHondawaraA | B9: =IF($A8="","","low") -> low | D9: 15 | E9: =IF(AND($D9="",COUNT($K9:$AH9)=0),"",IF(K9="",0,MAX(0,NETWORKDAYS(K9,IF(L9<>"",L9,IF($J9<>"",K9,$AI$1)),祝日!$A$2:$A$200)))+IF(M9="",0,MAX(0,NETWORKDAYS(M9,IF(N9<>"",N9,IF($J9<>"",M9,$AI$1)),祝日!$A$2:$A$200)))+IF(O9="",0,MAX(0,NETWORKDAYS(O9,IF(P9<>"",P9,IF($J9<>"",O9,$AI$1)),祝日!$A$2:$A$200)))+IF(Q9="",0,MAX(0,NETWORKDAYS(Q9,IF(R9<>"",R9,IF($J9<>"",Q9,$AI$1)),祝日!$A$2:$A$200)))+IF(S9="",0,MAX(0,NETWORKDAYS(S9,IF(T9<>"",T9,IF($J9<>"",S9,$AI$1)),祝日!$A$2:$A$200)))+IF(U9="",0,MAX(0,NETWORKDAYS(U9,IF(V9<>"",V9,IF($J9<>"",U9,$AI$1)),祝日!$A$2:$A$200)))+IF(W9="",0,MAX(0,NETWORKDAYS(W9,IF(X9<>"",X9,IF($J9<>"",W9,$AI$1)),祝日!$A$2:$A$200)))+IF(Y9="",0,MAX(0,NETWORKDAYS(Y9,IF(Z9<>"",Z9,IF($J9<>"",Y9,$AI$1)),祝日!$A$2:$A$200)))+IF(AA9="",0,MAX(0,NETWORKDAYS(AA9,IF(AB9<>"",AB9,IF($J9<>"",AA9,$AI$1)),祝日!$A$2:$A$200)))+IF(AC9="",0,MAX(0,NETWORKDAYS(AC9,IF(AD9<>"",AD9,IF($J9<>"",AC9,$AI$1)),祝日!$A$2:$A$200)))+IF(AE9="",0,MAX(0,NETWORKDAYS(AE9,IF(AF9<>"",AF9,IF($J9<>"",AE9,$AI$1)),祝日!$A$2:$A$200)))+IF(AG9="",0,MAX(0,NETWORKDAYS(AG9,IF(AH9<>"",AH9,IF($J9<>"",AG9,$AI$1)),祝日!$A$2:$A$200)))) -> 6 | F9: =IF($D9="","",$D9-$E9) -> 9 | G9: =IF(OR($D9="",$D9=0),"",$E9/$D9) -> 0.4 | H9: =IF($D9="","",IF($J9<>"","FIX",IF(AND(SUMPRODUCT((MOD(COLUMN($K9:$AH9)-COLUMN($K9),2)=0)*($K9:$AH9<>""))=0,SUMPRODUCT((MOD(COLUMN($K9:$AH9)-COLUMN($K9),2)=1)*($K9:$AH9<>""))=0),"未着手",IF(SUMPRODUCT((MOD(COLUMN($K9:$AH9)-COLUMN($K9),2)=0)*($K9:$AH9<>""))>SUMPRODUCT((MOD(COLUMN($K9:$AH9)-COLUMN($K9),2)=1)*($K9:$AH9<>"")),"作業中","中断")))) -> 作業中 | I9: =IF($H9="中断",MAX(0,$AI$1-MAX(L9,N9,P9,R9,T9,V9,X9,Z9,AB9,AD9,AF9,AH9)),"") | K9: 46283 | L9: 46294 | M9: 46302 | AK9: =IF($A8="","",IF(LOOKUP(2,1/($AJ$3:$AJ9<>""),$AJ$3:$AJ9)="-","",LOOKUP(2,1/($AJ$3:$AJ9<>""),$AJ$3:$AJ9))) -> CH01 | AL9: =$H9 -> 作業中 | AM9: =IF(ISNUMBER($D9),$D9,0) -> 15 | AN9: =IF(ISNUMBER($E9),$E9,0) -> 6 | AO9: =IF(ISNUMBER($F9),$F9,0) -> 9 | AQ9: =IF(OR($AK9="",K9="",L9=""),0,COUNTIFS($AK$3:$AK$98,$AK9,K$3:K$98,"<"&L9,L$3:L$98,">"&K9)+COUNTIFS($AK$3:$AK$98,$AK9,M$3:M$98,"<"&L9,N$3:N$98,">"&K9)+COUNTIFS($AK$3:$AK$98,$AK9,O$3:O$98,"<"&L9,P$3:P$98,">"&K9)+COUNTIFS($AK$3:$AK$98,$AK9,Q$3:Q$98,"<"&L9,R$3:R$98,">"&K9)+COUNTIFS($AK$3:$AK$98,$AK9,S$3:S$98,"<"&L9,T$3:T$98,">"&K9)+COUNTIFS($AK$3:$AK$98,$AK9,U$3:U$98,"<"&L9,V$3:V$98,">"&K9)+COUNTIFS($AK$3:$AK$98,$AK9,W$3:W$98,"<"&L9,X$3:X$98,">"&K9)+COUNTIFS($AK$3:$AK$98,$AK9,Y$3:Y$98,"<"&L9,Z$3:Z$98,">"&K9)+COUNTIFS($AK$3:$AK$98,$AK9,AA$3:AA$98,"<"&L9,AB$3:AB$98,">"&K9)+COUNTIFS($AK$3:$AK$98,$AK9,AC$3:AC$98,"<"&L9,AD$3:AD$98,">"&K9)+COUNTIFS($AK$3:$AK$98,$AK9,AE$3:AE$98,"<"&L9,AF$3:AF$98,">"&K9)+COUNTIFS($AK$3:$AK$98,$AK9,AG$3:AG$98,"<"&L9,AH$3:AH$98,">"&K9)-(K9<L9)) -> 0 | AR9: =AQ9 -> 0 | AS9: =IF(OR($AK9="",M9="",N9=""),0,COUNTIFS($AK$3:$AK$98,$AK9,K$3:K$98,"<"&N9,L$3:L$98,">"&M9)+COUNTIFS($AK$3:$AK$98,$AK9,M$3:M$98,"<"&N9,N$3:N$98,">"&M9)+COUNTIFS($AK$3:$AK$98,$AK9,O$3:O$98,"<"&N9,P$3:P$98,">"&M9)+COUNTIFS($AK$3:$AK$98,$AK9,Q$3:Q$98,"<"&N9,R$3:R$98,">"&M9)+COUNTIFS($AK$3:$AK$98,$AK9,S$3:S$98,"<"&N9,T$3:T$98,">"&M9)+COUNTIFS($AK$3:$AK$98,$AK9,U$3:U$98,"<"&N9,V$3:V$98,">"&M9)+COUNTIFS($AK$3:$AK$98,$AK9,W$3:W$98,"<"&N9,X$3:X$98,">"&M9)+COUNTIFS($AK$3:$AK$98,$AK9,Y$3:Y$98,"<"&N9,Z$3:Z$98,">"&M9)+COUNTIFS($AK$3:$AK$98,$AK9,AA$3:AA$98,"<"&N9,AB$3:AB$98,">"&M9)+COUNTIFS($AK$3:$AK$98,$AK9,AC$3:AC$98,"<"&N9,AD$3:AD$98,">"&M9)+COUNTIFS($AK$3:$AK$98,$AK9,AE$3:AE$98,"<"&N9,AF$3:AF$98,">"&M9)+COUNTIFS($AK$3:$AK$98,$AK9,AG$3:AG$98,"<"&N9,AH$3:AH$98,">"&M9)-(M9<N9)) -> 0 | AT9: =AS9 -> 0 | AU9: =IF(OR($AK9="",O9="",P9=""),0,COUNTIFS($AK$3:$AK$98,$AK9,K$3:K$98,"<"&P9,L$3:L$98,">"&O9)+COUNTIFS($AK$3:$AK$98,$AK9,M$3:M$98,"<"&P9,N$3:N$98,">"&O9)+COUNTIFS($AK$3:$AK$98,$AK9,O$3:O$98,"<"&P9,P$3:P$98,">"&O9)+COUNTIFS($AK$3:$AK$98,$AK9,Q$3:Q$98,"<"&P9,R$3:R$98,">"&O9)+COUNTIFS($AK$3:$AK$98,$AK9,S$3:S$98,"<"&P9,T$3:T$98,">"&O9)+COUNTIFS($AK$3:$AK$98,$AK9,U$3:U$98,"<"&P9,V$3:V$98,">"&O9)+COUNTIFS($AK$3:$AK$98,$AK9,W$3:W$98,"<"&P9,X$3:X$98,">"&O9)+COUNTIFS($AK$3:$AK$98,$AK9,Y$3:Y$98,"<"&P9,Z$3:Z$98,">"&O9)+COUNTIFS($AK$3:$AK$98,$AK9,AA$3:AA$98,"<"&P9,AB$3:AB$98,">"&O9)+COUNTIFS($AK$3:$AK$98,$AK9,AC$3:AC$98,"<"&P9,AD$3:AD$98,">"&O9)+COUNTIFS($AK$3:$AK$98,$AK9,AE$3:AE$98,"<"&P9,AF$3:AF$98,">"&O9)+COUNTIFS($AK$3:$AK$98,$AK9,AG$3:AG$98,"<"&P9,AH$3:AH$98,">"&O9)-(O9<P9)) -> 0 | AV9: =AU9 -> 0 | AW9: =IF(OR($AK9="",Q9="",R9=""),0,COUNTIFS($AK$3:$AK$98,$AK9,K$3:K$98,"<"&R9,L$3:L$98,">"&Q9)+COUNTIFS($AK$3:$AK$98,$AK9,M$3:M$98,"<"&R9,N$3:N$98,">"&Q9)+COUNTIFS($AK$3:$AK$98,$AK9,O$3:O$98,"<"&R9,P$3:P$98,">"&Q9)+COUNTIFS($AK$3:$AK$98,$AK9,Q$3:Q$98,"<"&R9,R$3:R$98,">"&Q9)+COUNTIFS($AK$3:$AK$98,$AK9,S$3:S$98,"<"&R9,T$3:T$98,">"&Q9)+COUNTIFS($AK$3:$AK$98,$AK9,U$3:U$98,"<"&R9,V$3:V$98,">"&Q9)+COUNTIFS($AK$3:$AK$98,$AK9,W$3:W$98,"<"&R9,X$3:X$98,">"&Q9)+COUNTIFS($AK$3:$AK$98,$AK9,Y$3:Y$98,"<"&R9,Z$3:Z$98,">"&Q9)+COUNTIFS($AK$3:$AK$98,$AK9,AA$3:AA$98,"<"&R9,AB$3:AB$98,">"&Q9)+COUNTIFS($AK$3:$AK$98,$AK9,AC$3:AC$98,"<"&R9,AD$3:AD$98,">"&Q9)+COUNTIFS($AK$3:$AK$98,$AK9,AE$3:AE$98,"<"&R9,AF$3:AF$98,">"&Q9)+COUNTIFS($AK$3:$AK$98,$AK9,AG$3:AG$98,"<"&R9,AH$3:AH$98,">"&Q9)-(Q9<R9)) -> 0 | AX9: =AW9 -> 0 | AY9: =IF(OR($AK9="",S9="",T9=""),0,COUNTIFS($AK$3:$AK$98,$AK9,K$3:K$98,"<"&T9,L$3:L$98,">"&S9)+COUNTIFS($AK$3:$AK$98,$AK9,M$3:M$98,"<"&T9,N$3:N$98,">"&S9)+COUNTIFS($AK$3:$AK$98,$AK9,O$3:O$98,"<"&T9,P$3:P$98,">"&S9)+COUNTIFS($AK$3:$AK$98,$AK9,Q$3:Q$98,"<"&T9,R$3:R$98,">"&S9)+COUNTIFS($AK$3:$AK$98,$AK9,S$3:S$98,"<"&T9,T$3:T$98,">"&S9)+COUNTIFS($AK$3:$AK$98,$AK9,U$3:U$98,"<"&T9,V$3:V$98,">"&S9)+COUNTIFS($AK$3:$AK$98,$AK9,W$3:W$98,"<"&T9,X$3:X$98,">"&S9)+COUNTIFS($AK$3:$AK$98,$AK9,Y$3:Y$98,"<"&T9,Z$3:Z$98,">"&S9)+COUNTIFS($AK$3:$AK$98,$AK9,AA$3:AA$98,"<"&T9,AB$3:AB$98,">"&S9)+COUNTIFS($AK$3:$AK$98,$AK9,AC$3:AC$98,"<"&T9,AD$3:AD$98,">"&S9)+COUNTIFS($AK$3:$AK$98,$AK9,AE$3:AE$98,"<"&T9,AF$3:AF$98,">"&S9)+COUNTIFS($AK$3:$AK$98,$AK9,AG$3:AG$98,"<"&T9,AH$3:AH$98,">"&S9)-(S9<T9)) -> 0 | AZ9: =AY9 -> 0 | BA9: =IF(OR($AK9="",U9="",V9=""),0,COUNTIFS($AK$3:$AK$98,$AK9,K$3:K$98,"<"&V9,L$3:L$98,">"&U9)+COUNTIFS($AK$3:$AK$98,$AK9,M$3:M$98,"<"&V9,N$3:N$98,">"&U9)+COUNTIFS($AK$3:$AK$98,$AK9,O$3:O$98,"<"&V9,P$3:P$98,">"&U9)+COUNTIFS($AK$3:$AK$98,$AK9,Q$3:Q$98,"<"&V9,R$3:R$98,">"&U9)+COUNTIFS($AK$3:$AK$98,$AK9,S$3:S$98,"<"&V9,T$3:T$98,">"&U9)+COUNTIFS($AK$3:$AK$98,$AK9,U$3:U$98,"<"&V9,V$3:V$98,">"&U9)+COUNTIFS($AK$3:$AK$98,$AK9,W$3:W$98,"<"&V9,X$3:X$98,">"&U9)+COUNTIFS($AK$3:$AK$98,$AK9,Y$3:Y$98,"<"&V9,Z$3:Z$98,">"&U9)+COUNTIFS($AK$3:$AK$98,$AK9,AA$3:AA$98,"<"&V9,AB$3:AB$98,">"&U9)+COUNTIFS($AK$3:$AK$98,$AK9,AC$3:AC$98,"<"&V9,AD$3:AD$98,">"&U9)+COUNTIFS($AK$3:$AK$98,$AK9,AE$3:AE$98,"<"&V9,AF$3:AF$98,">"&U9)+COUNTIFS($AK$3:$AK$98,$AK9,AG$3:AG$98,"<"&V9,AH$3:AH$98,">"&U9)-(U9<V9)) -> 0 | BB9: =BA9 -> 0 | BC9: =IF(OR($AK9="",W9="",X9=""),0,COUNTIFS($AK$3:$AK$98,$AK9,K$3:K$98,"<"&X9,L$3:L$98,">"&W9)+COUNTIFS($AK$3:$AK$98,$AK9,M$3:M$98,"<"&X9,N$3:N$98,">"&W9)+COUNTIFS($AK$3:$AK$98,$AK9,O$3:O$98,"<"&X9,P$3:P$98,">"&W9)+COUNTIFS($AK$3:$AK$98,$AK9,Q$3:Q$98,"<"&X9,R$3:R$98,">"&W9)+COUNTIFS($AK$3:$AK$98,$AK9,S$3:S$98,"<"&X9,T$3:T$98,">"&W9)+COUNTIFS($AK$3:$AK$98,$AK9,U$3:U$98,"<"&X9,V$3:V$98,">"&W9)+COUNTIFS($AK$3:$AK$98,$AK9,W$3:W$98,"<"&X9,X$3:X$98,">"&W9)+COUNTIFS($AK$3:$AK$98,$AK9,Y$3:Y$98,"<"&X9,Z$3:Z$98,">"&W9)+COUNTIFS($AK$3:$AK$98,$AK9,AA$3:AA$98,"<"&X9,AB$3:AB$98,">"&W9)+COUNTIFS($AK$3:$AK$98,$AK9,AC$3:AC$98,"<"&X9,AD$3:AD$98,">"&W9)+COUNTIFS($AK$3:$AK$98,$AK9,AE$3:AE$98,"<"&X9,AF$3:AF$98,">"&W9)+COUNTIFS($AK$3:$AK$98,$AK9,AG$3:AG$98,"<"&X9,AH$3:AH$98,">"&W9)-(W9<X9)) -> 0 | BD9: =BC9 -> 0 | BE9: =IF(OR($AK9="",Y9="",Z9=""),0,COUNTIFS($AK$3:$AK$98,$AK9,K$3:K$98,"<"&Z9,L$3:L$98,">"&Y9)+COUNTIFS($AK$3:$AK$98,$AK9,M$3:M$98,"<"&Z9,N$3:N$98,">"&Y9)+COUNTIFS($AK$3:$AK$98,$AK9,O$3:O$98,"<"&Z9,P$3:P$98,">"&Y9)+COUNTIFS($AK$3:$AK$98,$AK9,Q$3:Q$98,"<"&Z9,R$3:R$98,">"&Y9)+COUNTIFS($AK$3:$AK$98,$AK9,S$3:S$98,"<"&Z9,T$3:T$98,">"&Y9)+COUNTIFS($AK$3:$AK$98,$AK9,U$3:U$98,"<"&Z9,V$3:V$98,">"&Y9)+COUNTIFS($AK$3:$AK$98,$AK9,W$3:W$98,"<"&Z9,X$3:X$98,">"&Y9)+COUNTIFS($AK$3:$AK$98,$AK9,Y$3:Y$98,"<"&Z9,Z$3:Z$98,">"&Y9)+COUNTIFS($AK$3:$AK$98,$AK9,AA$3:AA$98,"<"&Z9,AB$3:AB$98,">"&Y9)+COUNTIFS($AK$3:$AK$98,$AK9,AC$3:AC$98,"<"&Z9,AD$3:AD$98,">"&Y9)+COUNTIFS($AK$3:$AK$98,$AK9,AE$3:AE$98,"<"&Z9,AF$3:AF$98,">"&Y9)+COUNTIFS($AK$3:$AK$98,$AK9,AG$3:AG$98,"<"&Z9,AH$3:AH$98,">"&Y9)-(Y9<Z9)) -> 0 | BF9: =BE9 -> 0 | BG9: =IF(OR($AK9="",AA9="",AB9=""),0,COUNTIFS($AK$3:$AK$98,$AK9,K$3:K$98,"<"&AB9,L$3:L$98,">"&AA9)+COUNTIFS($AK$3:$AK$98,$AK9,M$3:M$98,"<"&AB9,N$3:N$98,">"&AA9)+COUNTIFS($AK$3:$AK$98,$AK9,O$3:O$98,"<"&AB9,P$3:P$98,">"&AA9)+COUNTIFS($AK$3:$AK$98,$AK9,Q$3:Q$98,"<"&AB9,R$3:R$98,">"&AA9)+COUNTIFS($AK$3:$AK$98,$AK9,S$3:S$98,"<"&AB9,T$3:T$98,">"&AA9)+COUNTIFS($AK$3:$AK$98,$AK9,U$3:U$98,"<"&AB9,V$3:V$98,">"&AA9)+COUNTIFS($AK$3:$AK$98,$AK9,W$3:W$98,"<"&AB9,X$3:X$98,">"&AA9)+COUNTIFS($AK$3:$AK$98,$AK9,Y$3:Y$98,"<"&AB9,Z$3:Z$98,">"&AA9)+COUNTIFS($AK$3:$AK$98,$AK9,AA$3:AA$98,"<"&AB9,AB$3:AB$98,">"&AA9)+COUNTIFS($AK$3:$AK$98,$AK9,AC$3:AC$98,"<"&AB9,AD$3:AD$98,">"&AA9)+COUNTIFS($AK$3:$AK$98,$AK9,AE$3:AE$98,"<"&AB9,AF$3:AF$98,">"&AA9)+COUNTIFS($AK$3:$AK$98,$AK9,AG$3:AG$98,"<"&AB9,AH$3:AH$98,">"&AA9)-(AA9<AB9)) -> 0 | BH9: =BG9 -> 0 | BI9: =IF(OR($AK9="",AC9="",AD9=""),0,COUNTIFS($AK$3:$AK$98,$AK9,K$3:K$98,"<"&AD9,L$3:L$98,">"&AC9)+COUNTIFS($AK$3:$AK$98,$AK9,M$3:M$98,"<"&AD9,N$3:N$98,">"&AC9)+COUNTIFS($AK$3:$AK$98,$AK9,O$3:O$98,"<"&AD9,P$3:P$98,">"&AC9)+COUNTIFS($AK$3:$AK$98,$AK9,Q$3:Q$98,"<"&AD9,R$3:R$98,">"&AC9)+COUNTIFS($AK$3:$AK$98,$AK9,S$3:S$98,"<"&AD9,T$3:T$98,">"&AC9)+COUNTIFS($AK$3:$AK$98,$AK9,U$3:U$98,"<"&AD9,V$3:V$98,">"&AC9)+COUNTIFS($AK$3:$AK$98,$AK9,W$3:W$98,"<"&AD9,X$3:X$98,">"&AC9)+COUNTIFS($AK$3:$AK$98,$AK9,Y$3:Y$98,"<"&AD9,Z$3:Z$98,">"&AC9)+COUNTIFS($AK$3:$AK$98,$AK9,AA$3:AA$98,"<"&AD9,AB$3:AB$98,">"&AC9)+COUNTIFS($AK$3:$AK$98,$AK9,AC$3:AC$98,"<"&AD9,AD$3:AD$98,">"&AC9)+COUNTIFS($AK$3:$AK$98,$AK9,AE$3:AE$98,"<"&AD9,AF$3:AF$98,">"&AC9)+COUNTIFS($AK$3:$AK$98,$AK9,AG$3:AG$98,"<"&AD9,AH$3:AH$98,">"&AC9)-(AC9<AD9)) -> 0 | BJ9: =BI9 -> 0 | BK9: =IF(OR($AK9="",AE9="",AF9=""),0,COUNTIFS($AK$3:$AK$98,$AK9,K$3:K$98,"<"&AF9,L$3:L$98,">"&AE9)+COUNTIFS($AK$3:$AK$98,$AK9,M$3:M$98,"<"&AF9,N$3:N$98,">"&AE9)+COUNTIFS($AK$3:$AK$98,$AK9,O$3:O$98,"<"&AF9,P$3:P$98,">"&AE9)+COUNTIFS($AK$3:$AK$98,$AK9,Q$3:Q$98,"<"&AF9,R$3:R$98,">"&AE9)+COUNTIFS($AK$3:$AK$98,$AK9,S$3:S$98,"<"&AF9,T$3:T$98,">"&AE9)+COUNTIFS($AK$3:$AK$98,$AK9,U$3:U$98,"<"&AF9,V$3:V$98,">"&AE9)+COUNTIFS($AK$3:$AK$98,$AK9,W$3:W$98,"<"&AF9,X$3:X$98,">"&AE9)+COUNTIFS($AK$3:$AK$98,$AK9,Y$3:Y$98,"<"&AF9,Z$3:Z$98,">"&AE9)+COUNTIFS($AK$3:$AK$98,$AK9,AA$3:AA$98,"<"&AF9,AB$3:AB$98,">"&AE9)+COUNTIFS($AK$3:$AK$98,$AK9,AC$3:AC$98,"<"&AF9,AD$3:AD$98,">"&AE9)+COUNTIFS($AK$3:$AK$98,$AK9,AE$3:AE$98,"<"&AF9,AF$3:AF$98,">"&AE9)+COUNTIFS($AK$3:$AK$98,$AK9,AG$3:AG$98,"<"&AF9,AH$3:AH$98,">"&AE9)-(AE9<AF9)) -> 0 | BL9: =BK9 -> 0 | BM9: =IF(OR($AK9="",AG9="",AH9=""),0,COUNTIFS($AK$3:$AK$98,$AK9,K$3:K$98,"<"&AH9,L$3:L$98,">"&AG9)+COUNTIFS($AK$3:$AK$98,$AK9,M$3:M$98,"<"&AH9,N$3:N$98,">"&AG9)+COUNTIFS($AK$3:$AK$98,$AK9,O$3:O$98,"<"&AH9,P$3:P$98,">"&AG9)+COUNTIFS($AK$3:$AK$98,$AK9,Q$3:Q$98,"<"&AH9,R$3:R$98,">"&AG9)+COUNTIFS($AK$3:$AK$98,$AK9,S$3:S$98,"<"&AH9,T$3:T$98,">"&AG9)+COUNTIFS($AK$3:$AK$98,$AK9,U$3:U$98,"<"&AH9,V$3:V$98,">"&AG9)+COUNTIFS($AK$3:$AK$98,$AK9,W$3:W$98,"<"&AH9,X$3:X$98,">"&AG9)+COUNTIFS($AK$3:$AK$98,$AK9,Y$3:Y$98,"<"&AH9,Z$3:Z$98,">"&AG9)+COUNTIFS($AK$3:$AK$98,$AK9,AA$3:AA$98,"<"&AH9,AB$3:AB$98,">"&AG9)+COUNTIFS($AK$3:$AK$98,$AK9,AC$3:AC$98,"<"&AH9,AD$3:AD$98,">"&AG9)+COUNTIFS($AK$3:$AK$98,$AK9,AE$3:AE$98,"<"&AH9,AF$3:AF$98,">"&AG9)+COUNTIFS($AK$3:$AK$98,$AK9,AG$3:AG$98,"<"&AH9,AH$3:AH$98,">"&AG9)-(AG9<AH9)) -> 0 | BN9: =BM9 -> 0 | BO9: =IF(ISNUMBER($G9),$G9,"") -> 0.4 | BP9: =IF(AND($A9<>"",COUNT($K9:$AH9)>0),ROW(),"") -> 9
